Workbook
Name TRANSMUTATION_TABLE: 'DO NOT DELETE'!$G$2:$J$42

Sheet Q1 math and epp
A1: THIRD QUARTER
C5: REGION | G5: ='INPUT DATA'!G4 -> 1 | N5: DIVISION | Q5: ='INPUT DATA'!O4 -> LA UNION | U5: DISTRICT | Y5: ='INPUT DATA'!X4 -> BALAOAN
B6: SCHOOL NAME | G6: ='INPUT DATA'!G5 -> MASUPE ELEMENTARY SCHOOL | U6: SCHOOL ID | Y6: ='INPUT DATA'!X5 -> 100882
B8: LEARNERS' NAMES | F8: GRADE & SECTION: | M8: ='INPUT DATA'!K7 -> 6-RIZAL | U8: SCHOOL YEAR: | Y8: ='INPUT DATA'!AG5 -> 2025 - 2026
F9: TEACHER: | M9: ='INPUT DATA'!S7 -> ROSEL E. SANCHEZ | U9: SUBJECT: | Y9: ='INPUT DATA'!AG7 -> 0
F10: MATH | L10: MATH | P10: MATH | T10: MATH | X10: MATH | AB10: MATH
F11: SUMMATIVE | L11: PERFORMANCE | P11: SUMMATIVE | T11: PERFORMANCE | X11: SUMMATIVE | AB11: PERFORMANCE
B12: MALE | F12: 1 | G12: 2 | H12: 3 | I12: 4 | K12: p | L12: 1 | M12: 2 | N12: 3 | O12: 4 | P12: 1 | Q12: 2 | R12: 3 | S12: 4 | T12: pt | U12: 2 | V12: 3 | W12: 4 | X12: 25 | Y12: 15 | Z12: 40
A13: 1 | B13: ='INPUT DATA'!B12 -> BUENDIA, Renz O.
A14: 2 | B14: ='INPUT DATA'!B13 -> DELOS SANTOS, Erlych D.
A15: 3 | B15: ='INPUT DATA'!B14 -> ESTRADA, Euan Kyle G.
A16: 4 | B16: ='INPUT DATA'!B15 -> FERRER, Alden Richard P.
A17: 5 | B17: ='INPUT DATA'!B16 -> MENDOZA, Jack Russel L.
A18: 6 | B18: ='INPUT DATA'!B17 -> OBRA, Jharain Z.
A19: 7 | B19: ='INPUT DATA'!B18 -> ORILLOS, Lance Darrielle C.
A20: 8 | B20: ='INPUT DATA'!B19 -> ORILLOS, Xian Gabriel B. | D20: 0
A21: 9 | B21: ='INPUT DATA'!B20 -> OSOTEO, Clyne Jhay M.
A22: 10 | B22: ='INPUT DATA'!B21 -> OSOTEO, Jharie Liam A.
A23: 11 | B23: ='INPUT DATA'!B22 -> RONQUILLO, Benz Darylle H. | D23: 0
A24: 12 | B24: ='INPUT DATA'!B28 -> 0
B25: FEMALE | AB25: =IF(OR($F25="",$L25="",$P25="",$T25="",$X25=""),"",IF($X25>=75,"PASSED","FAILED"))
A26: 1 | B26: ='INPUT DATA'!B30 -> CARDENAS, Zui Ai Gerryne A,
A27: 2 | B27: ='INPUT DATA'!B31 -> MAON, Kyle Rhean O.
A28: 3 | B28: ='INPUT DATA'!B32 -> MENDOZA, Ashley Keith O.
A29: 4 | B29: ='INPUT DATA'!B33 -> NERI, Arvienne P.
A30: 5 | B30: ='INPUT DATA'!B34 -> OPEÑA, Gracelyn May O.
A31: 6 | B31: ='INPUT DATA'!B35 -> PEÑAFIEL, Jandie V.
A32: 7 | B32: ='INPUT DATA'!B36 -> RIVERA, Eliska Catalina O.
A33: 8 | B33: ='INPUT DATA'!B37 -> VALDEZ, Angel Noreen R.
A34: 9 | B34: ='INPUT DATA'!B38 -> VILLAR, Veronica Mae F.
A35: 10 | B35: ='INPUT DATA'!B39 -> 0
A36: 11 | B36: ='INPUT DATA'!B47 -> 0

Sheet INPUT DATA
A1: Input Data Sheet for E-Class Record
C4: REGION | G4: 1 | L4: DIVISION | O4: LA UNION | T4: DISTRICT | X4: BALAOAN
B5: SCHOOL NAME | G5: MASUPE ELEMENTARY SCHOOL | T5: SCHOOL ID | X5: 100882 | AD5: SCHOOL YEAR | AG5: 2025 - 2026
A7: FIRST QUARTER | F7: GRADE & SECTION: | K7: 6-RIZAL | Q7: TEACHER: | S7: ROSEL E. SANCHEZ | AC7: SUBJECT:
B8: LEARNERS' NAMES
B11: MALE
A12: 1 | B12: BUENDIA, Renz O. | D12: 0 | E12: 0
A13: 2 | B13: DELOS SANTOS, Erlych D. | D13: 0 | E13: 0
A14: 3 | B14: ESTRADA, Euan Kyle G. | D14: 0 | E14: 0
A15: 4 | B15: FERRER, Alden Richard P. | D15: 0 | E15: 0
A16: 5 | B16: MENDOZA, Jack Russel L. | D16: 0 | E16: 0
A17: 6 | B17: OBRA, Jharain Z. | D17: 0 | E17: 0
A18: 7 | B18: ORILLOS, Lance Darrielle C. | D18: 0 | E18: 0
A19: 8 | B19: ORILLOS, Xian Gabriel B. | D19: 0 | E19: 0
A20: 9 | B20: OSOTEO, Clyne Jhay M. | D20: 0 | E20: 0
A21: 10 | B21: OSOTEO, Jharie Liam A. | D21: 0 | E21: 0
A22: 11 | B22: RONQUILLO, Benz Darylle H. | D22: 0 | E22: 0
A23: 12 | B23: SOMERA, Lucky Edward V.
A24: 13 | B24: VILLAR, Jim Bruno A.
C28: 0 | D28: 0 | E28: 0
B29: FEMALE
A30: 1 | B30: CARDENAS, Zui Ai Gerryne A, | C30: 0 | D30: 0 | E30: 0
A31: 2 | B31: MAON, Kyle Rhean O. | C31: 0 | D31: 0 | E31: 0
A32: 3 | B32: MENDOZA, Ashley Keith O. | C32: 0 | D32: 0 | E32: 0
A33: 4 | B33: NERI, Arvienne P. | C33: 0 | D33: 0 | E33: 0
A34: 5 | B34: OPEÑA, Gracelyn May O. | C34: 0 | D34: 0 | E34: 0
A35: 6 | B35: PEÑAFIEL, Jandie V. | C35: 0 | D35: 0 | E35: 0
A36: 7 | B36: RIVERA, Eliska Catalina O. | C36: 0 | D36: 0 | E36: 0
A37: 8 | B37: VALDEZ, Angel Noreen R. | C37: 0 | D37: 0 | E37: 0
A38: 9 | B38: VILLAR, Veronica Mae F. | C38: 0 | D38: 0 | E38: 0
C39: 0 | D39: 0 | E39: 0
A47: 11 | C47: 0 | D47: 0 | E47: 0

Sheet FIL_Q4
A1: Class Record
A3: (Pursuant to Deped Order 8 series of 2015)
C4: REGION | G4: ='INPUT DATA'!G4 -> 1 | L4: DIVISION | O4: ='INPUT DATA'!O4 -> LA UNION | T4: DISTRICT | X4: ='INPUT DATA'!X4 -> BALAOAN
B5: SCHOOL NAME | G5: ='INPUT DATA'!G5 -> MASUPE ELEMENTARY SCHOOL | T5: SCHOOL ID | X5: ='INPUT DATA'!X5 -> 100882 | AD5: SCHOOL YEAR | AG5: ='INPUT DATA'!AG5 -> 2025 - 2026
A7: FOURTH QUARTER | F7: GRADE & SECTION: | K7: 6-RIZAL | Q7: TEACHER: | S7: ROSEL E. SANCHEZ | AC7: SUBJECT: | AG7: FILIPINO
B8: LEARNERS' NAMES | F8: WRITTEN WORKS (30%) | S8: PERFORMANCE TASKS (50%) | AF8: QUARTERLY ASSESSMENT (20%) | AI8: Initial | AJ8: Quarterly
F9: 1 | G9: 2 | H9: 3 | I9: 4 | J9: 5 | K9: 6 | L9: 7 | M9: 8 | N9: 9 | O9: 10 | P9: Total | Q9: PS | R9: WS | S9: 1 | T9: 2 | U9: 3 | V9: 4 | W9: 5 | X9: 6 | Y9: 7 | Z9: 8 | AA9: 9 | AB9: 10 | AC9: Total | AD9: PS | AE9: WS | AF9: 1 | AG9: PS | AH9: WS | AI9: Grade | AJ9: Grade
B10: HIGHEST POSSIBLE SCORE | F10: 15 | G10: 15 | H10: 20 | P10: =IF(COUNT($F10:$O10)=0,"",SUM($F10:$O10)) -> 50 | Q10: 100 | R10: 0.3 | S10: 5 | T10: 10 | U10: 50 | AC10: =IF(COUNT($S10:$AB10)=0,"",SUM($S10:$AB10)) -> 65 | AD10: 100 | AE10: 0.5 | AF10: 40 | AG10: 100 | AH10: 0.2
B11: MALE | F11: Q1 | G11: Q2 | H11: Q3 | S11: Q1-patalastas | T11: Q2 | U11: saling magkaugnay | AM11: 3rd | AN11: 2nd | AO11: 1st
A12: 1 | B12: ='INPUT DATA'!B12 -> BUENDIA, Renz O. | F12: 13 | G12: 13 | H12: 19 | P12: =IF(COUNT($F12:$O12)=0,"",SUM($F12:$O12)) -> 45 | Q12: =IF(ISERROR(IF($P12="","",ROUND(($P12/$P$10)*$Q$10,2))),"",IF($P12="","",ROUND(($P12/$P$10)*$Q$10,2))) -> 90 | R12: =IF($Q12="","",ROUND($Q12*$R$10,2)) -> 27 | S12: 5 | T12: 10 | U12: 45 | AC12: =IF(COUNT($S12:$AB12)=0,"",SUM($S12:$AB12)) -> 60 | AD12: =IF(ISERROR(IF($AC12="","",ROUND(($AC12/$AC$10)*$AD$10,2))),"",IF($AC12="","",ROUND(($AC12/$AC$10)*$AD$10,2))) -> 92.31 | AE12: =IF($AD12="","",ROUND($AD12*$AE$10,2)) -> 46.16 | AF12: 30 | AG12: =IF(ISERROR(IF($AF12="","",ROUND(($AF12/$AF$10)*$AG$10,2))),"",IF($AF12="","",ROUND(($AF12/$AF$10)*$AG$10,2))) -> 75 | AH12: =IF($AG12="","",ROUND($AG12*$AH$10,2)) -> 15 | AI12: =IF(ISERROR(IF($AF12="","",ROUND(SUM($R12,$AE12,$AH12),2))),"",IF($AF12="","",ROUND(SUM($R12,$AE12,$AH12),2))) -> 88.16 | AJ12: =IF(ISERROR(IF($AF12="","",VLOOKUP(AI12,TRANSMUTATION_TABLE,4,TRUE))),"",IF($AF12="","",VLOOKUP(AI12,TRANSMUTATION_TABLE,4,TRUE))) -> 92 | AM12: 91 | AN12: 88 | AO12: 83
A13: 2 | B13: ='INPUT DATA'!B13 -> DELOS SANTOS, Erlych D. | F13: 12 | G13: 13 | H13: 18 | P13: =IF(COUNT($F13:$O13)=0,"",SUM($F13:$O13)) -> 43 | Q13: =IF(ISERROR(IF($P13="","",ROUND(($P13/$P$10)*$Q$10,2))),"",IF($P13="","",ROUND(($P13/$P$10)*$Q$10,2))) -> 86 | R13: =IF($Q13="","",ROUND($Q13*$R$10,2)) -> 25.8 | S13: 5 | T13: 10 | U13: 48 | AC13: =IF(COUNT($S13:$AB13)=0,"",SUM($S13:$AB13)) -> 63 | AD13: =IF(ISERROR(IF($AC13="","",ROUND(($AC13/$AC$10)*$AD$10,2))),"",IF($AC13="","",ROUND(($AC13/$AC$10)*$AD$10,2))) -> 96.92 | AE13: =IF($AD13="","",ROUND($AD13*$AE$10,2)) -> 48.46 | AF13: 33 | AG13: =IF(ISERROR(IF($AF13="","",ROUND(($AF13/$AF$10)*$AG$10,2))),"",IF($AF13="","",ROUND(($AF13/$AF$10)*$AG$10,2))) -> 82.5 | AH13: =IF($AG13="","",ROUND($AG13*$AH$10,2)) -> 16.5 | AI13: =IF(ISERROR(IF($AF13="","",ROUND(SUM($R13,$AE13,$AH13),2))),"",IF($AF13="","",ROUND(SUM($R13,$AE13,$AH13),2))) -> 90.76 | AJ13: =IF(ISERROR(IF($AF13="","",VLOOKUP(AI13,TRANSMUTATION_TABLE,4,TRUE))),"",IF($AF13="","",VLOOKUP(AI13,TRANSMUTATION_TABLE,4,TRUE))) -> 94 | AM13: 93 | AN13: 92 | AO13: 89
A14: 3 | B14: ='INPUT DATA'!B14 -> ESTRADA, Euan Kyle G. | F14: 15 | G14: 15 | H14: 15 | P14: =IF(COUNT($F14:$O14)=0,"",SUM($F14:$O14)) -> 45 | Q14: =IF(ISERROR(IF($P14="","",ROUND(($P14/$P$10)*$Q$10,2))),"",IF($P14="","",ROUND(($P14/$P$10)*$Q$10,2))) -> 90 | R14: =IF($Q14="","",ROUND($Q14*$R$10,2)) -> 27 | S14: 5 | T14: 10 | U14: 49 | AC14: =IF(COUNT($S14:$AB14)=0,"",SUM($S14:$AB14)) -> 64 | AD14: =IF(ISERROR(IF($AC14="","",ROUND(($AC14/$AC$10)*$AD$10,2))),"",IF($AC14="","",ROUND(($AC14/$AC$10)*$AD$10,2))) -> 98.46 | AE14: =IF($AD14="","",ROUND($AD14*$AE$10,2)) -> 49.23 | AF14: 38 | AG14: =IF(ISERROR(IF($AF14="","",ROUND(($AF14/$AF$10)*$AG$10,2))),"",IF($AF14="","",ROUND(($AF14/$AF$10)*$AG$10,2))) -> 95 | AH14: =IF($AG14="","",ROUND($AG14*$AH$10,2)) -> 19 | AI14: =IF(ISERROR(IF($AF14="","",ROUND(SUM($R14,$AE14,$AH14),2))),"",IF($AF14="","",ROUND(SUM($R14,$AE14,$AH14),2))) -> 95.23 | AJ14: =IF(ISERROR(IF($AF14="","",VLOOKUP(AI14,TRANSMUTATION_TABLE,4,TRUE))),"",IF($AF14="","",VLOOKUP(AI14,TRANSMUTATION_TABLE,4,TRUE))) -> 97 | AM14: 96 | AN14: 95 | AO14: 93
A15: 4 | B15: ='INPUT DATA'!B15 -> FERRER, Alden Richard P. | F15: 11 | G15: 15 | H15: 14 | P15: =IF(COUNT($F15:$O15)=0,"",SUM($F15:$O15)) -> 40 | Q15: =IF(ISERROR(IF($P15="","",ROUND(($P15/$P$10)*$Q$10,2))),"",IF($P15="","",ROUND(($P15/$P$10)*$Q$10,2))) -> 80 | R15: =IF($Q15="","",ROUND($Q15*$R$10,2)) -> 24 | S15: 3 | T15: 10 | U15: 45 | AC15: =IF(COUNT($S15:$AB15)=0,"",SUM($S15:$AB15)) -> 58 | AD15: =IF(ISERROR(IF($AC15="","",ROUND(($AC15/$AC$10)*$AD$10,2))),"",IF($AC15="","",ROUND(($AC15/$AC$10)*$AD$10,2))) -> 89.23 | AE15: =IF($AD15="","",ROUND($AD15*$AE$10,2)) -> 44.62 | AF15: 27 | AG15: =IF(ISERROR(IF($AF15="","",ROUND(($AF15/$AF$10)*$AG$10,2))),"",IF($AF15="","",ROUND(($AF15/$AF$10)*$AG$10,2))) -> 67.5 | AH15: =IF($AG15="","",ROUND($AG15*$AH$10,2)) -> 13.5 | AI15: =IF(ISERROR(IF($AF15="","",ROUND(SUM($R15,$AE15,$AH15),2))),"",IF($AF15="","",ROUND(SUM($R15,$AE15,$AH15),2))) -> 82.12 | AJ15: =IF(ISERROR(IF($AF15="","",VLOOKUP(AI15,TRANSMUTATION_TABLE,4,TRUE))),"",IF($AF15="","",VLOOKUP(AI15,TRANSMUTATION_TABLE,4,TRUE))) -> 88 | AM15: 87 | AN15: 86 | AO15: 81
A16: 5 | B16: ='INPUT DATA'!B16 -> MENDOZA, Jack Russel L. | F16: 14 | G16: 15 | H16: 20 | P16: =IF(COUNT($F16:$O16)=0,"",SUM($F16:$O16)) -> 49 | Q16: =IF(ISERROR(IF($P16="","",ROUND(($P16/$P$10)*$Q$10,2))),"",IF($P16="","",ROUND(($P16/$P$10)*$Q$10,2))) -> 98 | R16: =IF($Q16="","",ROUND($Q16*$R$10,2)) -> 29.4 | S16: 3 | T16: 10 | U16: 47 | AC16: =IF(COUNT($S16:$AB16)=0,"",SUM($S16:$AB16)) -> 60 | AD16: =IF(ISERROR(IF($AC16="","",ROUND(($AC16/$AC$10)*$AD$10,2))),"",IF($AC16="","",ROUND(($AC16/$AC$10)*$AD$10,2))) -> 92.31 | AE16: =IF($AD16="","",ROUND($AD16*$AE$10,2)) -> 46.16 | AF16: 37 | AG16: =IF(ISERROR(IF($AF16="","",ROUND(($AF16/$AF$10)*$AG$10,2))),"",IF($AF16="","",ROUND(($AF16/$AF$10)*$AG$10,2))) -> 92.5 | AH16: =IF($AG16="","",ROUND($AG16*$AH$10,2)) -> 18.5 | AI16: =IF(ISERROR(IF($AF16="","",ROUND(SUM($R16,$AE16,$AH16),2))),"",IF($AF16="","",ROUND(SUM($R16,$AE16,$AH16),2))) -> 94.06 | AJ16: =IF(ISERROR(IF($AF16="","",VLOOKUP(AI16,TRANSMUTATION_TABLE,4,TRUE))),"",IF($AF16="","",VLOOKUP(AI16,TRANSMUTATION_TABLE,4,TRUE))) -> 96 | AM16: 93 | AN16: 92 | AO16: 87
A17: 6 | B17: ='INPUT DATA'!B17 -> OBRA, Jharain Z. | F17: 14 | G17: 15 | H17: 19 | P17: =IF(COUNT($F17:$O17)=0,"",SUM($F17:$O17)) -> 48 | Q17: =IF(ISERROR(IF($P17="","",ROUND(($P17/$P$10)*$Q$10,2))),"",IF($P17="","",ROUND(($P17/$P$10)*$Q$10,2))) -> 96 | R17: =IF($Q17="","",ROUND($Q17*$R$10,2)) -> 28.8 | S17: 5 | T17: 10 | U17: 49 | AC17: =IF(COUNT($S17:$AB17)=0,"",SUM($S17:$AB17)) -> 64 | AD17: =IF(ISERROR(IF($AC17="","",ROUND(($AC17/$AC$10)*$AD$10,2))),"",IF($AC17="","",ROUND(($AC17/$AC$10)*$AD$10,2))) -> 98.46 | AE17: =IF($AD17="","",ROUND($AD17*$AE$10,2)) -> 49.23 | AF17: 39 | AG17: =IF(ISERROR(IF($AF17="","",ROUND(($AF17/$AF$10)*$AG$10,2))),"",IF($AF17="","",ROUND(($AF17/$AF$10)*$AG$10,2))) -> 97.5 | AH17: =IF($AG17="","",ROUND($AG17*$AH$10,2)) -> 19.5 | AI17: =IF(ISERROR(IF($AF17="","",ROUND(SUM($R17,$AE17,$AH17),2))),"",IF($AF17="","",ROUND(SUM($R17,$AE17,$AH17),2))) -> 97.53 | AJ17: =IF(ISERROR(IF($AF17="","",VLOOKUP(AI17,TRANSMUTATION_TABLE,4,TRUE))),"",IF($AF17="","",VLOOKUP(AI17,TRANSMUTATION_TABLE,4,TRUE))) -> 98 | AM17: 98 | AN17: 96 | AO17: 95
A18: 7 | B18: ='INPUT DATA'!B18 -> ORILLOS, Lance Darrielle C. | F18: 13 | G18: 13 | H18: 18 | P18: =IF(COUNT($F18:$O18)=0,"",SUM($F18:$O18)) -> 44 | Q18: =IF(ISERROR(IF($P18="","",ROUND(($P18/$P$10)*$Q$10,2))),"",IF($P18="","",ROUND(($P18/$P$10)*$Q$10,2))) -> 88 | R18: =IF($Q18="","",ROUND($Q18*$R$10,2)) -> 26.4 | S18: 5 | T18: 10 | U18: 47 | AC18: =IF(COUNT($S18:$AB18)=0,"",SUM($S18:$AB18)) -> 62 | AD18: =IF(ISERROR(IF($AC18="","",ROUND(($AC18/$AC$10)*$AD$10,2))),"",IF($AC18="","",ROUND(($AC18/$AC$10)*$AD$10,2))) -> 95.38 | AE18: =IF($AD18="","",ROUND($AD18*$AE$10,2)) -> 47.69 | AF18: 34 | AG18: =IF(ISERROR(IF($AF18="","",ROUND(($AF18/$AF$10)*$AG$10,2))),"",IF($AF18="","",ROUND(($AF18/$AF$10)*$AG$10,2))) -> 85 | AH18: =IF($AG18="","",ROUND($AG18*$AH$10,2)) -> 17 | AI18: =IF(ISERROR(IF($AF18="","",ROUND(SUM($R18,$AE18,$AH18),2))),"",IF($AF18="","",ROUND(SUM($R18,$AE18,$AH18),2))) -> 91.09 | AJ18: =IF(ISERROR(IF($AF18="","",VLOOKUP(AI18,TRANSMUTATION_TABLE,4,TRUE))),"",IF($AF18="","",VLOOKUP(AI18,TRANSMUTATION_TABLE,4,TRUE))) -> 94 | AM18: 92 | AN18: 91 | AO18: 85
A19: 8 | B19: ='INPUT DATA'!B19 -> ORILLOS, Xian Gabriel B. | D19: 0 | F19: 11 | G19: 12 | H19: 18 | P19: =IF(COUNT($F19:$O19)=0,"",SUM($F19:$O19)) -> 41 | Q19: =IF(ISERROR(IF($P19="","",ROUND(($P19/$P$10)*$Q$10,2))),"",IF($P19="","",ROUND(($P19/$P$10)*$Q$10,2))) -> 82 | R19: =IF($Q19="","",ROUND($Q19*$R$10,2)) -> 24.6 | S19: 5 | T19: 10 | U19: 45 | AC19: =IF(COUNT($S19:$AB19)=0,"",SUM($S19:$AB19)) -> 60 | AD19: =IF(ISERROR(IF($AC19="","",ROUND(($AC19/$AC$10)*$AD$10,2))),"",IF($AC19="","",ROUND(($AC19/$AC$10)*$AD$10,2))) -> 92.31 | AE19: =IF($AD19="","",ROUND($AD19*$AE$10,2)) -> 46.16 | AF19: 32 | AG19: =IF(ISERROR(IF($AF19="","",ROUND(($AF19/$AF$10)*$AG$10,2))),"",IF($AF19="","",ROUND(($AF19/$AF$10)*$AG$10,2))) -> 80 | AH19: =IF($AG19="","",ROUND($AG19*$AH$10,2)) -> 16 | AI19: =IF(ISERROR(IF($AF19="","",ROUND(SUM($R19,$AE19,$AH19),2))),"",IF($AF19="","",ROUND(SUM($R19,$AE19,$AH19),2))) -> 86.76 | AJ19: =IF(ISERROR(IF($AF19="","",VLOOKUP(AI19,TRANSMUTATION_TABLE,4,TRUE))),"",IF($AF19="","",VLOOKUP(AI19,TRANSMUTATION_TABLE,4,TRUE))) -> 91 | AM19: 88 | AN19: 86 | AO19: 81
A20: 9 | B20: ='INPUT DATA'!B20 -> OSOTEO, Clyne Jhay M. | F20: 14 | G20: 12 | H20: 18 | P20: =IF(COUNT($F20:$O20)=0,"",SUM($F20:$O20)) -> 44 | Q20: =IF(ISERROR(IF($P20="","",ROUND(($P20/$P$10)*$Q$10,2))),"",IF($P20="","",ROUND(($P20/$P$10)*$Q$10,2))) -> 88 | R20: =IF($Q20="","",ROUND($Q20*$R$10,2)) -> 26.4 | S20: 5 | T20: 10 | U20: 45 | AC20: =IF(COUNT($S20:$AB20)=0,"",SUM($S20:$AB20)) -> 60 | AD20: =IF(ISERROR(IF($AC20="","",ROUND(($AC20/$AC$10)*$AD$10,2))),"",IF($AC20="","",ROUND(($AC20/$AC$10)*$AD$10,2))) -> 92.31 | AE20: =IF($AD20="","",ROUND($AD20*$AE$10,2)) -> 46.16 | AF20: 31 | AG20: =IF(ISERROR(IF($AF20="","",ROUND(($AF20/$AF$10)*$AG$10,2))),"",IF($AF20="","",ROUND(($AF20/$AF$10)*$AG$10,2))) -> 77.5 | AH20: =IF($AG20="","",ROUND($AG20*$AH$10,2)) -> 15.5 | AI20: =IF(ISERROR(IF($AF20="","",ROUND(SUM($R20,$AE20,$AH20),2))),"",IF($AF20="","",ROUND(SUM($R20,$AE20,$AH20),2))) -> 88.06 | AJ20: =IF(ISERROR(IF($AF20="","",VLOOKUP(AI20,TRANSMUTATION_TABLE,4,TRUE))),"",IF($AF20="","",VLOOKUP(AI20,TRANSMUTATION_TABLE,4,TRUE))) -> 92 | AM20: 91 | AN20: 90 | AO20: 83
A21: 10 | B21: ='INPUT DATA'!B21 -> OSOTEO, Jharie Liam A. | F21: 12 | G21: 11 | H21: 13 | P21: =IF(COUNT($F21:$O21)=0,"",SUM($F21:$O21)) -> 36 | Q21: =IF(ISERROR(IF($P21="","",ROUND(($P21/$P$10)*$Q$10,2))),"",IF($P21="","",ROUND(($P21/$P$10)*$Q$10,2))) -> 72 | R21: =IF($Q21="","",ROUND($Q21*$R$10,2)) -> 21.6 | S21: 5 | T21: 10 | U21: 47 | AC21: =IF(COUNT($S21:$AB21)=0,"",SUM($S21:$AB21)) -> 62 | AD21: =IF(ISERROR(IF($AC21="","",ROUND(($AC21/$AC$10)*$AD$10,2))),"",IF($AC21="","",ROUND(($AC21/$AC$10)*$AD$10,2))) -> 95.38 | AE21: =IF($AD21="","",ROUND($AD21*$AE$10,2)) -> 47.69 | AF21: 30 | AG21: =IF(ISERROR(IF($AF21="","",ROUND(($AF21/$AF$10)*$AG$10,2))),"",IF($AF21="","",ROUND(($AF21/$AF$10)*$AG$10,2))) -> 75 | AH21: =IF($AG21="","",ROUND($AG21*$AH$10,2)) -> 15 | AI21: =IF(ISERROR(IF($AF21="","",ROUND(SUM($R21,$AE21,$AH21),2))),"",IF($AF21="","",ROUND(SUM($R21,$AE21,$AH21),2))) -> 84.29 | AJ21: =IF(ISERROR(IF($AF21="","",VLOOKUP(AI21,TRANSMUTATION_TABLE,4,TRUE))),"",IF($AF21="","",VLOOKUP(AI21,TRANSMUTATION_TABLE,4,TRUE))) -> 90 | AM21: 88 | AN21: 87 | AO21: 83
A22: 11 | B22: ='INPUT DATA'!B22 -> RONQUILLO, Benz Darylle H. | D22: 0 | F22: 15 | G22: 15 | H22: 18 | P22: =IF(COUNT($F22:$O22)=0,"",SUM($F22:$O22)) -> 48 | Q22: =IF(ISERROR(IF($P22="","",ROUND(($P22/$P$10)*$Q$10,2))),"",IF($P22="","",ROUND(($P22/$P$10)*$Q$10,2))) -> 96 | R22: =IF($Q22="","",ROUND($Q22*$R$10,2)) -> 28.8 | S22: 5 | T22: 10 | U22: 50 | AC22: =IF(COUNT($S22:$AB22)=0,"",SUM($S22:$AB22)) -> 65 | AD22: =IF(ISERROR(IF($AC22="","",ROUND(($AC22/$AC$10)*$AD$10,2))),"",IF($AC22="","",ROUND(($AC22/$AC$10)*$AD$10,2))) -> 100 | AE22: =IF($AD22="","",ROUND($AD22*$AE$10,2)) -> 50 | AF22: 36 | AG22: =IF(ISERROR(IF($AF22="","",ROUND(($AF22/$AF$10)*$AG$10,2))),"",IF($AF22="","",ROUND(($AF22/$AF$10)*$AG$10,2))) -> 90 | AH22: =IF($AG22="","",ROUND($AG22*$AH$10,2)) -> 18 | AI22: =IF(ISERROR(IF($AF22="","",ROUND(SUM($R22,$AE22,$AH22),2))),"",IF($AF22="","",ROUND(SUM($R22,$AE22,$AH22),2))) -> 96.8 | AJ22: =IF(ISERROR(IF($AF22="","",VLOOKUP(AI22,TRANSMUTATION_TABLE,4,TRUE))),"",IF($AF22="","",VLOOKUP(AI22,TRANSMUTATION_TABLE,4,TRUE))) -> 98 | AM22: 95 | AN22: 94 | AO22: 91
A23: 12 | B23: ='INPUT DATA'!B23 -> SOMERA, Lucky Edward V. | F23: 11 | G23: 11 | H23: 20 | P23: =IF(COUNT($F23:$O23)=0,"",SUM($F23:$O23)) -> 42 | Q23: =IF(ISERROR(IF($P23="","",ROUND(($P23/$P$10)*$Q$10,2))),"",IF($P23="","",ROUND(($P23/$P$10)*$Q$10,2))) -> 84 | R23: =IF($Q23="","",ROUND($Q23*$R$10,2)) -> 25.2 | S23: 5 | T23: 10 | U23: 48 | AC23: =IF(COUNT($S23:$AB23)=0,"",SUM($S23:$AB23)) -> 63 | AD23: =IF(ISERROR(IF($AC23="","",ROUND(($AC23/$AC$10)*$AD$10,2))),"",IF($AC23="","",ROUND(($AC23/$AC$10)*$AD$10,2))) -> 96.92 | AE23: =IF($AD23="","",ROUND($AD23*$AE$10,2)) -> 48.46 | AF23: 32 | AG23: =IF(ISERROR(IF($AF23="","",ROUND(($AF23/$AF$10)*$AG$10,2))),"",IF($AF23="","",ROUND(($AF23/$AF$10)*$AG$10,2))) -> 80 | AH23: =IF($AG23="","",ROUND($AG23*$AH$10,2)) -> 16 | AI23: =IF(ISERROR(IF($AF23="","",ROUND(SUM($R23,$AE23,$AH23),2))),"",IF($AF23="","",ROUND(SUM($R23,$AE23,$AH23),2))) -> 89.66 | AJ23: =IF(ISERROR(IF($AF23="","",VLOOKUP(AI23,TRANSMUTATION_TABLE,4,TRUE))),"",IF($AF23="","",VLOOKUP(AI23,TRANSMUTATION_TABLE,4,TRUE))) -> 93 | AM23: 91 | AN23: 90 | AO23: 88
A24: 13 | B24: ='INPUT DATA'!B24 -> VILLAR, Jim Bruno A. | F24: 13 | G24: 12 | H24: 17 | P24: =IF(COUNT($F24:$O24)=0,"",SUM($F24:$O24)) -> 42 | Q24: =IF(ISERROR(IF($P24="","",ROUND(($P24/$P$10)*$Q$10,2))),"",IF($P24="","",ROUND(($P24/$P$10)*$Q$10,2))) -> 84 | R24: =IF($Q24="","",ROUND($Q24*$R$10,2)) -> 25.2 | S24: 5 | T24: 10 | U24: 47 | AC24: =IF(COUNT($S24:$AB24)=0,"",SUM($S24:$AB24)) -> 62 | AD24: =IF(ISERROR(IF($AC24="","",ROUND(($AC24/$AC$10)*$AD$10,2))),"",IF($AC24="","",ROUND(($AC24/$AC$10)*$AD$10,2))) -> 95.38 | AE24: =IF($AD24="","",ROUND($AD24*$AE$10,2)) -> 47.69 | AF24: 30 | AG24: =IF(ISERROR(IF($AF24="","",ROUND(($AF24/$AF$10)*$AG$10,2))),"",IF($AF24="","",ROUND(($AF24/$AF$10)*$AG$10,2))) -> 75 | AH24: =IF($AG24="","",ROUND($AG24*$AH$10,2)) -> 15 | AI24: =IF(ISERROR(IF($AF24="","",ROUND(SUM($R24,$AE24,$AH24),2))),"",IF($AF24="","",ROUND(SUM($R24,$AE24,$AH24),2))) -> 87.89 | AJ24: =IF(ISERROR(IF($AF24="","",VLOOKUP(AI24,TRANSMUTATION_TABLE,4,TRUE))),"",IF($AF24="","",VLOOKUP(AI24,TRANSMUTATION_TABLE,4,TRUE))) -> 92 | AM24: 91 | AN24: 90 | AO24: 86
B25: ='INPUT DATA'!B27 -> 0 | P25: =IF(COUNT($F25:$O25)=0,"",SUM($F25:$O25)) | Q25: =IF(ISERROR(IF($P25="","",ROUND(($P25/$P$10)*$Q$10,2))),"",IF($P25="","",ROUND(($P25/$P$10)*$Q$10,2))) | R25: =IF($Q25="","",ROUND($Q25*$R$10,2)) | AC25: =IF(COUNT($S25:$AB25)=0,"",SUM($S25:$AB25)) | AD25: =IF(ISERROR(IF($AC25="","",ROUND(($AC25/$AC$10)*$AD$10,2))),"",IF($AC25="","",ROUND(($AC25/$AC$10)*$AD$10,2))) | AE25: =IF($AD25="","",ROUND($AD25*$AE$10,2)) | AG25: =IF(ISERROR(IF($AF25="","",ROUND(($AF25/$AF$10)*$AG$10,2))),"",IF($AF25="","",ROUND(($AF25/$AF$10)*$AG$10,2))) | AH25: =IF($AG25="","",ROUND($AG25*$AH$10,2)) | AI25: =IF(ISERROR(IF($AF25="","",ROUND(SUM($R25,$AE25,$AH25),2))),"",IF($AF25="","",ROUND(SUM($R25,$AE25,$AH25),2))) | AJ25: =IF(ISERROR(IF($AF25="","",VLOOKUP(AI25,TRANSMUTATION_TABLE,4,TRUE))),"",IF($AF25="","",VLOOKUP(AI25,TRANSMUTATION_TABLE,4,TRUE)))
B26: FEMALE
A27: 1 | B27: ='INPUT DATA'!B30 -> CARDENAS, Zui Ai Gerryne A, | F27: 13 | G27: 14 | H27: 14 | P27: =IF(COUNT($F27:$O27)=0,"",SUM($F27:$O27)) -> 41 | Q27: =IF(ISERROR(IF($P27="","",ROUND(($P27/$P$10)*$Q$10,2))),"",IF($P27="","",ROUND(($P27/$P$10)*$Q$10,2))) -> 82 | R27: =IF($Q27="","",ROUND($Q27*$R$10,2)) -> 24.6 | S27: 5 | T27: 10 | U27: 47 | AC27: =IF(COUNT($S27:$AB27)=0,"",SUM($S27:$AB27)) -> 62 | AD27: =IF(ISERROR(IF($AC27="","",ROUND(($AC27/$AC$10)*$AD$10,2))),"",IF($AC27="","",ROUND(($AC27/$AC$10)*$AD$10,2))) -> 95.38 | AE27: =IF($AD27="","",ROUND($AD27*$AE$10,2)) -> 47.69 | AF27: 34 | AG27: =IF(ISERROR(IF($AF27="","",ROUND(($AF27/$AF$10)*$AG$10,2))),"",IF($AF27="","",ROUND(($AF27/$AF$10)*$AG$10,2))) -> 85 | AH27: =IF($AG27="","",ROUND($AG27*$AH$10,2)) -> 17 | AI27: =IF(ISERROR(IF($AF27="","",ROUND(SUM($R27,$AE27,$AH27),2))),"",IF($AF27="","",ROUND(SUM($R27,$AE27,$AH27),2))) -> 89.29 | AJ27: =IF(ISERROR(IF($AF27="","",VLOOKUP(AI27,TRANSMUTATION_TABLE,4,TRUE))),"",IF($AF27="","",VLOOKUP(AI27,TRANSMUTATION_TABLE,4,TRUE))) -> 93 | AM27: 92 | AN27: 91 | AO27: 88
A28: 2 | B28: ='INPUT DATA'!B31 -> MAON, Kyle Rhean O. | F28: 12 | G28: 15 | H28: 13 | P28: =IF(COUNT($F28:$O28)=0,"",SUM($F28:$O28)) -> 40 | Q28: =IF(ISERROR(IF($P28="","",ROUND(($P28/$P$10)*$Q$10,2))),"",IF($P28="","",ROUND(($P28/$P$10)*$Q$10,2))) -> 80 | R28: =IF($Q28="","",ROUND($Q28*$R$10,2)) -> 24 | S28: 5 | T28: 10 | U28: 47 | AC28: =IF(COUNT($S28:$AB28)=0,"",SUM($S28:$AB28)) -> 62 | AD28: =IF(ISERROR(IF($AC28="","",ROUND(($AC28/$AC$10)*$AD$10,2))),"",IF($AC28="","",ROUND(($AC28/$AC$10)*$AD$10,2))) -> 95.38 | AE28: =IF($AD28="","",ROUND($AD28*$AE$10,2)) -> 47.69 | AF28: 32 | AG28: =IF(ISERROR(IF($AF28="","",ROUND(($AF28/$AF$10)*$AG$10,2))),"",IF($AF28="","",ROUND(($AF28/$AF$10)*$AG$10,2))) -> 80 | AH28: =IF($AG28="","",ROUND($AG28*$AH$10,2)) -> 16 | AI28: =IF(ISERROR(IF($AF28="","",ROUND(SUM($R28,$AE28,$AH28),2))),"",IF($AF28="","",ROUND(SUM($R28,$AE28,$AH28),2))) -> 87.69 | AJ28: =IF(ISERROR(IF($AF28="","",VLOOKUP(AI28,TRANSMUTATION_TABLE,4,TRUE))),"",IF($AF28="","",VLOOKUP(AI28,TRANSMUTATION_TABLE,4,TRUE))) -> 92 | AM28: 91 | AN28: 90 | AO28: 87
A29: 3 | B29: ='INPUT DATA'!B32 -> MENDOZA, Ashley Keith O. | F29: 14 | G29: 12 | H29: 14 | P29: =IF(COUNT($F29:$O29)=0,"",SUM($F29:$O29)) -> 40 | Q29: =IF(ISERROR(IF($P29="","",ROUND(($P29/$P$10)*$Q$10,2))),"",IF($P29="","",ROUND(($P29/$P$10)*$Q$10,2))) -> 80 | R29: =IF($Q29="","",ROUND($Q29*$R$10,2)) -> 24 | S29: 5 | T29: 10 | U29: 48 | AC29: =IF(COUNT($S29:$AB29)=0,"",SUM($S29:$AB29)) -> 63 | AD29: =IF(ISERROR(IF($AC29="","",ROUND(($AC29/$AC$10)*$AD$10,2))),"",IF($AC29="","",ROUND(($AC29/$AC$10)*$AD$10,2))) -> 96.92 | AE29: =IF($AD29="","",ROUND($AD29*$AE$10,2)) -> 48.46 | AF29: 33 | AG29: =IF(ISERROR(IF($AF29="","",ROUND(($AF29/$AF$10)*$AG$10,2))),"",IF($AF29="","",ROUND(($AF29/$AF$10)*$AG$10,2))) -> 82.5 | AH29: =IF($AG29="","",ROUND($AG29*$AH$10,2)) -> 16.5 | AI29: =IF(ISERROR(IF($AF29="","",ROUND(SUM($R29,$AE29,$AH29),2))),"",IF($AF29="","",ROUND(SUM($R29,$AE29,$AH29),2))) -> 88.96 | AJ29: =IF(ISERROR(IF($AF29="","",VLOOKUP(AI29,TRANSMUTATION_TABLE,4,TRUE))),"",IF($AF29="","",VLOOKUP(AI29,TRANSMUTATION_TABLE,4,TRUE))) -> 93 | AM29: 92 | AN29: 89 | AO29: 87
A30: 4 | B30: ='INPUT DATA'!B33 -> NERI, Arvienne P. | F30: 13 | G30: 15 | H30: 19 | P30: =IF(COUNT($F30:$O30)=0,"",SUM($F30:$O30)) -> 47 | Q30: =IF(ISERROR(IF($P30="","",ROUND(($P30/$P$10)*$Q$10,2))),"",IF($P30="","",ROUND(($P30/$P$10)*$Q$10,2))) -> 94 | R30: =IF($Q30="","",ROUND($Q30*$R$10,2)) -> 28.2 | S30: 5 | T30: 10 | U30: 49 | AC30: =IF(COUNT($S30:$AB30)=0,"",SUM($S30:$AB30)) -> 64 | AD30: =IF(ISERROR(IF($AC30="","",ROUND(($AC30/$AC$10)*$AD$10,2))),"",IF($AC30="","",ROUND(($AC30/$AC$10)*$AD$10,2))) -> 98.46 | AE30: =IF($AD30="","",ROUND($AD30*$AE$10,2)) -> 49.23 | AF30: 37 | AG30: =IF(ISERROR(IF($AF30="","",ROUND(($AF30/$AF$10)*$AG$10,2))),"",IF($AF30="","",ROUND(($AF30/$AF$10)*$AG$10,2))) -> 92.5 | AH30: =IF($AG30="","",ROUND($AG30*$AH$10,2)) -> 18.5 | AI30: =IF(ISERROR(IF($AF30="","",ROUND(SUM($R30,$AE30,$AH30),2))),"",IF($AF30="","",ROUND(SUM($R30,$AE30,$AH30),2))) -> 95.93 | AJ30: =IF(ISERROR(IF($AF30="","",VLOOKUP(AI30,TRANSMUTATION_TABLE,4,TRUE))),"",IF($AF30="","",VLOOKUP(AI30,TRANSMUTATION_TABLE,4,TRUE))) -> 97 | AM30: 96 | AN30: 95 | AO30: 92
A31: 5 | B31: ='INPUT DATA'!B34 -> OPEÑA, Gracelyn May O. | F31: 13 | G31: 15 | H31: 18 | P31: =IF(COUNT($F31:$O31)=0,"",SUM($F31:$O31)) -> 46 | Q31: =IF(ISERROR(IF($P31="","",ROUND(($P31/$P$10)*$Q$10,2))),"",IF($P31="","",ROUND(($P31/$P$10)*$Q$10,2))) -> 92 | R31: =IF($Q31="","",ROUND($Q31*$R$10,2)) -> 27.6 | S31: 5 | T31: 10 | U31: 48 | AC31: =IF(COUNT($S31:$AB31)=0,"",SUM($S31:$AB31)) -> 63 | AD31: =IF(ISERROR(IF($AC31="","",ROUND(($AC31/$AC$10)*$AD$10,2))),"",IF($AC31="","",ROUND(($AC31/$AC$10)*$AD$10,2))) -> 96.92 | AE31: =IF($AD31="","",ROUND($AD31*$AE$10,2)) -> 48.46 | AF31: 36 | AG31: =IF(ISERROR(IF($AF31="","",ROUND(($AF31/$AF$10)*$AG$10,2))),"",IF($AF31="","",ROUND(($AF31/$AF$10)*$AG$10,2))) -> 90 | AH31: =IF($AG31="","",ROUND($AG31*$AH$10,2)) -> 18 | AI31: =IF(ISERROR(IF($AF31="","",ROUND(SUM($R31,$AE31,$AH31),2))),"",IF($AF31="","",ROUND(SUM($R31,$AE31,$AH31),2))) -> 94.06 | AJ31: =IF(ISERROR(IF($AF31="","",VLOOKUP(AI31,TRANSMUTATION_TABLE,4,TRUE))),"",IF($AF31="","",VLOOKUP(AI31,TRANSMUTATION_TABLE,4,TRUE))) -> 96 | AM31: 95 | AN31: 94 | AO31: 93
A32: 6 | B32: ='INPUT DATA'!B35 -> PEÑAFIEL, Jandie V. | F32: 15 | G32: 14 | H32: 15 | P32: =IF(COUNT($F32:$O32)=0,"",SUM($F32:$O32)) -> 44 | Q32: =IF(ISERROR(IF($P32="","",ROUND(($P32/$P$10)*$Q$10,2))),"",IF($P32="","",ROUND(($P32/$P$10)*$Q$10,2))) -> 88 | R32: =IF($Q32="","",ROUND($Q32*$R$10,2)) -> 26.4 | S32: 5 | T32: 10 | U32: 48 | AC32: =IF(COUNT($S32:$AB32)=0,"",SUM($S32:$AB32)) -> 63 | AD32: =IF(ISERROR(IF($AC32="","",ROUND(($AC32/$AC$10)*$AD$10,2))),"",IF($AC32="","",ROUND(($AC32/$AC$10)*$AD$10,2))) -> 96.92 | AE32: =IF($AD32="","",ROUND($AD32*$AE$10,2)) -> 48.46 | AF32: 35 | AG32: =IF(ISERROR(IF($AF32="","",ROUND(($AF32/$AF$10)*$AG$10,2))),"",IF($AF32="","",ROUND(($AF32/$AF$10)*$AG$10,2))) -> 87.5 | AH32: =IF($AG32="","",ROUND($AG32*$AH$10,2)) -> 17.5 | AI32: =IF(ISERROR(IF($AF32="","",ROUND(SUM($R32,$AE32,$AH32),2))),"",IF($AF32="","",ROUND(SUM($R32,$AE32,$AH32),2))) -> 92.36 | AJ32: =IF(ISERROR(IF($AF32="","",VLOOKUP(AI32,TRANSMUTATION_TABLE,4,TRUE))),"",IF($AF32="","",VLOOKUP(AI32,TRANSMUTATION_TABLE,4,TRUE))) -> 95 | AM32: 93 | AN32: 92 | AO32: 91
A33: 7 | B33: ='INPUT DATA'!B36 -> RIVERA, Eliska Catalina O. | F33: 15 | G33: 15 | H33: 19 | P33: =IF(COUNT($F33:$O33)=0,"",SUM($F33:$O33)) -> 49 | Q33: =IF(ISERROR(IF($P33="","",ROUND(($P33/$P$10)*$Q$10,2))),"",IF($P33="","",ROUND(($P33/$P$10)*$Q$10,2))) -> 98 | R33: =IF($Q33="","",ROUND($Q33*$R$10,2)) -> 29.4 | S33: 5 | T33: 10 | U33: 50 | AC33: =IF(COUNT($S33:$AB33)=0,"",SUM($S33:$AB33)) -> 65 | AD33: =IF(ISERROR(IF($AC33="","",ROUND(($AC33/$AC$10)*$AD$10,2))),"",IF($AC33="","",ROUND(($AC33/$AC$10)*$AD$10,2))) -> 100 | AE33: =IF($AD33="","",ROUND($AD33*$AE$10,2)) -> 50 | AF33: 38 | AG33: =IF(ISERROR(IF($AF33="","",ROUND(($AF33/$AF$10)*$AG$10,2))),"",IF($AF33="","",ROUND(($AF33/$AF$10)*$AG$10,2))) -> 95 | AH33: =IF($AG33="","",ROUND($AG33*$AH$10,2)) -> 19 | AI33: =IF(ISERROR(IF($AF33="","",ROUND(SUM($R33,$AE33,$AH33),2))),"",IF($AF33="","",ROUND(SUM($R33,$AE33,$AH33),2))) -> 98.4 | AJ33: =IF(ISERROR(IF($AF33="","",VLOOKUP(AI33,TRANSMUTATION_TABLE,4,TRUE))),"",IF($AF33="","",VLOOKUP(AI33,TRANSMUTATION_TABLE,4,TRUE))) -> 99 | AM33: 98 | AN33: 97 | AO33: 96
A34: 8 | B34: ='INPUT DATA'!B37 -> VALDEZ, Angel Noreen R. | F34: 13 | G34: 14 | H34: 18 | P34: =IF(COUNT($F34:$O34)=0,"",SUM($F34:$O34)) -> 45 | Q34: =IF(ISERROR(IF($P34="","",ROUND(($P34/$P$10)*$Q$10,2))),"",IF($P34="","",ROUND(($P34/$P$10)*$Q$10,2))) -> 90 | R34: =IF($Q34="","",ROUND($Q34*$R$10,2)) -> 27 | S34: 5 | T34: 10 | U34: 49 | AC34: =IF(COUNT($S34:$AB34)=0,"",SUM($S34:$AB34)) -> 64 | AD34: =IF(ISERROR(IF($AC34="","",ROUND(($AC34/$AC$10)*$AD$10,2))),"",IF($AC34="","",ROUND(($AC34/$AC$10)*$AD$10,2))) -> 98.46 | AE34: =IF($AD34="","",ROUND($AD34*$AE$10,2)) -> 49.23 | AF34: 36 | AG34: =IF(ISERROR(IF($AF34="","",ROUND(($AF34/$AF$10)*$AG$10,2))),"",IF($AF34="","",ROUND(($AF34/$AF$10)*$AG$10,2))) -> 90 | AH34: =IF($AG34="","",ROUND($AG34*$AH$10,2)) -> 18 | AI34: =IF(ISERROR(IF($AF34="","",ROUND(SUM($R34,$AE34,$AH34),2))),"",IF($AF34="","",ROUND(SUM($R34,$AE34,$AH34),2))) -> 94.23 | AJ34: =IF(ISERROR(IF($AF34="","",VLOOKUP(AI34,TRANSMUTATION_TABLE,4,TRUE))),"",IF($AF34="","",VLOOKUP(AI34,TRANSMUTATION_TABLE,4,TRUE))) -> 96 | AM34: 95 | AN34: 94 | AO34: 90
A35: 9 | B35: ='INPUT DATA'!B38 -> VILLAR, Veronica Mae F. | F35: 13 | G35: 13 | H35: 17 | P35: =IF(COUNT($F35:$O35)=0,"",SUM($F35:$O35)) -> 43 | Q35: =IF(ISERROR(IF($P35="","",ROUND(($P35/$P$10)*$Q$10,2))),"",IF($P35="","",ROUND(($P35/$P$10)*$Q$10,2))) -> 86 | R35: =IF($Q35="","",ROUND($Q35*$R$10,2)) -> 25.8 | S35: 5 | T35: 10 | U35: 45 | AC35: =IF(COUNT($S35:$AB35)=0,"",SUM($S35:$AB35)) -> 60 | AD35: =IF(ISERROR(IF($AC35="","",ROUND(($AC35/$AC$10)*$AD$10,2))),"",IF($AC35="","",ROUND(($AC35/$AC$10)*$AD$10,2))) -> 92.31 | AE35: =IF($AD35="","",ROUND($AD35*$AE$10,2)) -> 46.16 | AF35: 33 | AG35: =IF(ISERROR(IF($AF35="","",ROUND(($AF35/$AF$10)*$AG$10,2))),"",IF($AF35="","",ROUND(($AF35/$AF$10)*$AG$10,2))) -> 82.5 | AH35: =IF($AG35="","",ROUND($AG35*$AH$10,2)) -> 16.5 | AI35: =IF(ISERROR(IF($AF35="","",ROUND(SUM($R35,$AE35,$AH35),2))),"",IF($AF35="","",ROUND(SUM($R35,$AE35,$AH35),2))) -> 88.46 | AJ35: =IF(ISERROR(IF($AF35="","",VLOOKUP(AI35,TRANSMUTATION_TABLE,4,TRUE))),"",IF($AF35="","",VLOOKUP(AI35,TRANSMUTATION_TABLE,4,TRUE))) -> 92 | AM35: 91 | AN35: 90 | AO35: 86
A36: 10 | B36: ='INPUT DATA'!B39 -> 0 | P36: =IF(COUNT($F36:$O36)=0,"",SUM($F36:$O36)) | Q36: =IF(ISERROR(IF($P36="","",ROUND(($P36/$P$10)*$Q$10,2))),"",IF($P36="","",ROUND(($P36/$P$10)*$Q$10,2))) | R36: =IF($Q36="","",ROUND($Q36*$R$10,2)) | AC36: =IF(COUNT($S36:$AB36)=0,"",SUM($S36:$AB36)) | AD36: =IF(ISERROR(IF($AC36="","",ROUND(($AC36/$AC$10)*$AD$10,2))),"",IF($AC36="","",ROUND(($AC36/$AC$10)*$AD$10,2))) | AE36: =IF($AD36="","",ROUND($AD36*$AE$10,2)) | AG36: =IF(ISERROR(IF($AF36="","",ROUND(($AF36/$AF$10)*$AG$10,2))),"",IF($AF36="","",ROUND(($AF36/$AF$10)*$AG$10,2))) | AH36: =IF($AG36="","",ROUND($AG36*$AH$10,2)) | AI36: =IF(ISERROR(IF($AF36="","",ROUND(SUM($R36,$AE36,$AH36),2))),"",IF($AF36="","",ROUND(SUM($R36,$AE36,$AH36),2))) | AJ36: =IF(ISERROR(IF($AF36="","",VLOOKUP(AI36,TRANSMUTATION_TABLE,4,TRUE))),"",IF($AF36="","",VLOOKUP(AI36,TRANSMUTATION_TABLE,4,TRUE)))
F37: =SUM(F12:F36) -> 289 | G37: =SUM(G12:G36) -> 299 | H37: =SUM(H12:H36) -> 374 | AF37: =SUM(AF12:AF36) -> 743
A38: MEAN | F38: =(SUM(F12:F36))/21 -> 13.761905 | G38: =(SUM(G12:G36))/21 -> 14.238095 | H38: =(SUM(H12:H36))/21 -> 17.809524 | AF38: =(SUM(AF12:AF36))/21 -> 35.380952
A39: % OF MASTERY | F39: =F38/F10*100 -> 91.746032 | G39: =G38/G10*100 -> 94.920635 | H39: =H38/H10*100 -> 89.047619 | AF39: =AF38/AF10*100 -> 88.452381
A41: Prepared by: | S41: Noted:
B42: ROSEL E. SANCHEZ | T42: ROMELYN O. OBALLES
B43: Master Teacher I | T43: Head Teacher III

Sheet ENG_Q4
A1: Class Record
A3: (Pursuant to Deped Order 8 series of 2015)
C4: REGION | G4: ='INPUT DATA'!G4 -> 1 | L4: DIVISION | O4: ='INPUT DATA'!O4 -> LA UNION | T4: DISTRICT | X4: ='INPUT DATA'!X4 -> BALAOAN
B5: SCHOOL NAME | G5: ='INPUT DATA'!G5 -> MASUPE ELEMENTARY SCHOOL | T5: SCHOOL ID | X5: ='INPUT DATA'!X5 -> 100882 | AD5: SCHOOL YEAR | AG5: ='INPUT DATA'!AG5 -> 2025 - 2026
A7: FOURTH QUARTER | F7: GRADE & SECTION: | K7: 6-RIZAL | Q7: TEACHER: | S7: ROSEL E. SANCHEZ | AC7: SUBJECT: | AG7: ENGLISH
B8: LEARNERS' NAMES | F8: WRITTEN WORKS (30%) | S8: PERFORMANCE TASKS (50%) | AF8: QUARTERLY ASSESSMENT (20%) | AI8: Initial | AJ8: Quarterly
F9: 1 | G9: 2 | H9: 3 | I9: 4 | J9: 5 | K9: 6 | L9: 7 | M9: 8 | N9: 9 | O9: 10 | P9: Total | Q9: PS | R9: WS | S9: 1 | T9: 2 | U9: 3 | V9: 4 | W9: 5 | X9: 6 | Y9: 7 | Z9: 8 | AA9: 9 | AB9: 10 | AC9: Total | AD9: PS | AE9: WS | AF9: 1 | AG9: PS | AH9: WS | AI9: Grade | AJ9: Grade
B10: HIGHEST POSSIBLE SCORE | F10: 20 | G10: 20 | H10: 15 | P10: =IF(COUNT($F10:$O10)=0,"",SUM($F10:$O10)) -> 55 | Q10: 100 | R10: 0.3 | S10: 10 | T10: 5 | U10: 20 | V10: 5 | AC10: =IF(COUNT($S10:$AB10)=0,"",SUM($S10:$AB10)) -> 40 | AD10: 100 | AE10: 0.5 | AF10: 40 | AG10: 100 | AH10: 0.2
B11: MALE | S11: myself | T11: recitation | U11: adverb & puzzle | V11: adv. Intensity | AK11: 1st | AN11: 2nd | AO11: 3rd
A12: 1 | B12: ='INPUT DATA'!B12 -> BUENDIA, Renz O. | F12: 13 | G12: 14 | H12: 13 | P12: =IF(COUNT($F12:$O12)=0,"",SUM($F12:$O12)) -> 40 | Q12: =IF(ISERROR(IF($P12="","",ROUND(($P12/$P$10)*$Q$10,2))),"",IF($P12="","",ROUND(($P12/$P$10)*$Q$10,2))) -> 72.73 | R12: =IF($Q12="","",ROUND($Q12*$R$10,2)) -> 21.82 | S12: 9 | T12: 4 | U12: 19 | V12: 5 | AC12: =IF(COUNT($S12:$AB12)=0,"",SUM($S12:$AB12)) -> 37 | AD12: =IF(ISERROR(IF($AC12="","",ROUND(($AC12/$AC$10)*$AD$10,2))),"",IF($AC12="","",ROUND(($AC12/$AC$10)*$AD$10,2))) -> 92.5 | AE12: =IF($AD12="","",ROUND($AD12*$AE$10,2)) -> 46.25 | AF12: 31 | AG12: =IF(ISERROR(IF($AF12="","",ROUND(($AF12/$AF$10)*$AG$10,2))),"",IF($AF12="","",ROUND(($AF12/$AF$10)*$AG$10,2))) -> 77.5 | AH12: =IF($AG12="","",ROUND($AG12*$AH$10,2)) -> 15.5 | AI12: =IF(ISERROR(IF($AF12="","",ROUND(SUM($R12,$AE12,$AH12),2))),"",IF($AF12="","",ROUND(SUM($R12,$AE12,$AH12),2))) -> 83.57 | AJ12: =IF(ISERROR(IF($AF12="","",VLOOKUP(AI12,TRANSMUTATION_TABLE,4,TRUE))),"",IF($AF12="","",VLOOKUP(AI12,TRANSMUTATION_TABLE,4,TRUE))) -> 89 | AK12: 81 | AN12: 85 | AO12: 87
A13: 2 | B13: ='INPUT DATA'!B13 -> DELOS SANTOS, Erlych D. | F13: 17 | G13: 16 | H13: 13 | P13: =IF(COUNT($F13:$O13)=0,"",SUM($F13:$O13)) -> 46 | Q13: =IF(ISERROR(IF($P13="","",ROUND(($P13/$P$10)*$Q$10,2))),"",IF($P13="","",ROUND(($P13/$P$10)*$Q$10,2))) -> 83.64 | R13: =IF($Q13="","",ROUND($Q13*$R$10,2)) -> 25.09 | S13: 9 | T13: 5 | U13: 20 | V13: 5 | AC13: =IF(COUNT($S13:$AB13)=0,"",SUM($S13:$AB13)) -> 39 | AD13: =IF(ISERROR(IF($AC13="","",ROUND(($AC13/$AC$10)*$AD$10,2))),"",IF($AC13="","",ROUND(($AC13/$AC$10)*$AD$10,2))) -> 97.5 | AE13: =IF($AD13="","",ROUND($AD13*$AE$10,2)) -> 48.75 | AF13: 30 | AG13: =IF(ISERROR(IF($AF13="","",ROUND(($AF13/$AF$10)*$AG$10,2))),"",IF($AF13="","",ROUND(($AF13/$AF$10)*$AG$10,2))) -> 75 | AH13: =IF($AG13="","",ROUND($AG13*$AH$10,2)) -> 15 | AI13: =IF(ISERROR(IF($AF13="","",ROUND(SUM($R13,$AE13,$AH13),2))),"",IF($AF13="","",ROUND(SUM($R13,$AE13,$AH13),2))) -> 88.84 | AJ13: =IF(ISERROR(IF($AF13="","",VLOOKUP(AI13,TRANSMUTATION_TABLE,4,TRUE))),"",IF($AF13="","",VLOOKUP(AI13,TRANSMUTATION_TABLE,4,TRUE))) -> 93 | AK13: 91 | AN13: 92 | AO13: 92
A14: 3 | B14: ='INPUT DATA'!B14 -> ESTRADA, Euan Kyle G. | F14: 19 | G14: 19 | H14: 14 | P14: =IF(COUNT($F14:$O14)=0,"",SUM($F14:$O14)) -> 52 | Q14: =IF(ISERROR(IF($P14="","",ROUND(($P14/$P$10)*$Q$10,2))),"",IF($P14="","",ROUND(($P14/$P$10)*$Q$10,2))) -> 94.55 | R14: =IF($Q14="","",ROUND($Q14*$R$10,2)) -> 28.37 | S14: 10 | T14: 5 | U14: 20 | V14: 5 | AC14: =IF(COUNT($S14:$AB14)=0,"",SUM($S14:$AB14)) -> 40 | AD14: =IF(ISERROR(IF($AC14="","",ROUND(($AC14/$AC$10)*$AD$10,2))),"",IF($AC14="","",ROUND(($AC14/$AC$10)*$AD$10,2))) -> 100 | AE14: =IF($AD14="","",ROUND($AD14*$AE$10,2)) -> 50 | AF14: 37 | AG14: =IF(ISERROR(IF($AF14="","",ROUND(($AF14/$AF$10)*$AG$10,2))),"",IF($AF14="","",ROUND(($AF14/$AF$10)*$AG$10,2))) -> 92.5 | AH14: =IF($AG14="","",ROUND($AG14*$AH$10,2)) -> 18.5 | AI14: =IF(ISERROR(IF($AF14="","",ROUND(SUM($R14,$AE14,$AH14),2))),"",IF($AF14="","",ROUND(SUM($R14,$AE14,$AH14),2))) -> 96.87 | AJ14: =IF(ISERROR(IF($AF14="","",VLOOKUP(AI14,TRANSMUTATION_TABLE,4,TRUE))),"",IF($AF14="","",VLOOKUP(AI14,TRANSMUTATION_TABLE,4,TRUE))) -> 98 | AK14: 96 | AN14: 97 | AO14: 97
A15: 4 | B15: ='INPUT DATA'!B15 -> FERRER, Alden Richard P. | F15: 13 | G15: 12 | H15: 13 | P15: =IF(COUNT($F15:$O15)=0,"",SUM($F15:$O15)) -> 38 | Q15: =IF(ISERROR(IF($P15="","",ROUND(($P15/$P$10)*$Q$10,2))),"",IF($P15="","",ROUND(($P15/$P$10)*$Q$10,2))) -> 69.09 | R15: =IF($Q15="","",ROUND($Q15*$R$10,2)) -> 20.73 | S15: 8 | T15: 4 | U15: 16 | V15: 3 | AC15: =IF(COUNT($S15:$AB15)=0,"",SUM($S15:$AB15)) -> 31 | AD15: =IF(ISERROR(IF($AC15="","",ROUND(($AC15/$AC$10)*$AD$10,2))),"",IF($AC15="","",ROUND(($AC15/$AC$10)*$AD$10,2))) -> 77.5 | AE15: =IF($AD15="","",ROUND($AD15*$AE$10,2)) -> 38.75 | AF15: 30 | AG15: =IF(ISERROR(IF($AF15="","",ROUND(($AF15/$AF$10)*$AG$10,2))),"",IF($AF15="","",ROUND(($AF15/$AF$10)*$AG$10,2))) -> 75 | AH15: =IF($AG15="","",ROUND($AG15*$AH$10,2)) -> 15 | AI15: =IF(ISERROR(IF($AF15="","",ROUND(SUM($R15,$AE15,$AH15),2))),"",IF($AF15="","",ROUND(SUM($R15,$AE15,$AH15),2))) -> 74.48 | AJ15: =IF(ISERROR(IF($AF15="","",VLOOKUP(AI15,TRANSMUTATION_TABLE,4,TRUE))),"",IF($AF15="","",VLOOKUP(AI15,TRANSMUTATION_TABLE,4,TRUE))) -> 84 | AK15: 79 | AN15: 83 | AO15: 83
A16: 5 | B16: ='INPUT DATA'!B16 -> MENDOZA, Jack Russel L. | F16: 18 | G16: 18 | H16: 13 | P16: =IF(COUNT($F16:$O16)=0,"",SUM($F16:$O16)) -> 49 | Q16: =IF(ISERROR(IF($P16="","",ROUND(($P16/$P$10)*$Q$10,2))),"",IF($P16="","",ROUND(($P16/$P$10)*$Q$10,2))) -> 89.09 | R16: =IF($Q16="","",ROUND($Q16*$R$10,2)) -> 26.73 | S16: 9 | T16: 5 | U16: 17 | V16: 5 | AC16: =IF(COUNT($S16:$AB16)=0,"",SUM($S16:$AB16)) -> 36 | AD16: =IF(ISERROR(IF($AC16="","",ROUND(($AC16/$AC$10)*$AD$10,2))),"",IF($AC16="","",ROUND(($AC16/$AC$10)*$AD$10,2))) -> 90 | AE16: =IF($AD16="","",ROUND($AD16*$AE$10,2)) -> 45 | AF16: 31 | AG16: =IF(ISERROR(IF($AF16="","",ROUND(($AF16/$AF$10)*$AG$10,2))),"",IF($AF16="","",ROUND(($AF16/$AF$10)*$AG$10,2))) -> 77.5 | AH16: =IF($AG16="","",ROUND($AG16*$AH$10,2)) -> 15.5 | AI16: =IF(ISERROR(IF($AF16="","",ROUND(SUM($R16,$AE16,$AH16),2))),"",IF($AF16="","",ROUND(SUM($R16,$AE16,$AH16),2))) -> 87.23 | AJ16: =IF(ISERROR(IF($AF16="","",VLOOKUP(AI16,TRANSMUTATION_TABLE,4,TRUE))),"",IF($AF16="","",VLOOKUP(AI16,TRANSMUTATION_TABLE,4,TRUE))) -> 92 | AK16: 85 | AN16: 87 | AO16: 89
A17: 6 | B17: ='INPUT DATA'!B17 -> OBRA, Jharain Z. | F17: 19 | G17: 20 | H17: 14 | P17: =IF(COUNT($F17:$O17)=0,"",SUM($F17:$O17)) -> 53 | Q17: =IF(ISERROR(IF($P17="","",ROUND(($P17/$P$10)*$Q$10,2))),"",IF($P17="","",ROUND(($P17/$P$10)*$Q$10,2))) -> 96.36 | R17: =IF($Q17="","",ROUND($Q17*$R$10,2)) -> 28.91 | S17: 10 | T17: 5 | U17: 20 | V17: 5 | AC17: =IF(COUNT($S17:$AB17)=0,"",SUM($S17:$AB17)) -> 40 | AD17: =IF(ISERROR(IF($AC17="","",ROUND(($AC17/$AC$10)*$AD$10,2))),"",IF($AC17="","",ROUND(($AC17/$AC$10)*$AD$10,2))) -> 100 | AE17: =IF($AD17="","",ROUND($AD17*$AE$10,2)) -> 50 | AF17: 36 | AG17: =IF(ISERROR(IF($AF17="","",ROUND(($AF17/$AF$10)*$AG$10,2))),"",IF($AF17="","",ROUND(($AF17/$AF$10)*$AG$10,2))) -> 90 | AH17: =IF($AG17="","",ROUND($AG17*$AH$10,2)) -> 18 | AI17: =IF(ISERROR(IF($AF17="","",ROUND(SUM($R17,$AE17,$AH17),2))),"",IF($AF17="","",ROUND(SUM($R17,$AE17,$AH17),2))) -> 96.91 | AJ17: =IF(ISERROR(IF($AF17="","",VLOOKUP(AI17,TRANSMUTATION_TABLE,4,TRUE))),"",IF($AF17="","",VLOOKUP(AI17,TRANSMUTATION_TABLE,4,TRUE))) -> 98 | AK17: 94 | AN17: 96 | AO17: 98
A18: 7 | B18: ='INPUT DATA'!B18 -> ORILLOS, Lance Darrielle C. | E18: 7 | F18: 13 | G18: 18 | H18: 13 | P18: =IF(COUNT($F18:$O18)=0,"",SUM($F18:$O18)) -> 44 | Q18: =IF(ISERROR(IF($P18="","",ROUND(($P18/$P$10)*$Q$10,2))),"",IF($P18="","",ROUND(($P18/$P$10)*$Q$10,2))) -> 80 | R18: =IF($Q18="","",ROUND($Q18*$R$10,2)) -> 24 | S18: 9 | T18: 5 | U18: 18 | V18: 5 | AC18: =IF(COUNT($S18:$AB18)=0,"",SUM($S18:$AB18)) -> 37 | AD18: =IF(ISERROR(IF($AC18="","",ROUND(($AC18/$AC$10)*$AD$10,2))),"",IF($AC18="","",ROUND(($AC18/$AC$10)*$AD$10,2))) -> 92.5 | AE18: =IF($AD18="","",ROUND($AD18*$AE$10,2)) -> 46.25 | AF18: 34 | AG18: =IF(ISERROR(IF($AF18="","",ROUND(($AF18/$AF$10)*$AG$10,2))),"",IF($AF18="","",ROUND(($AF18/$AF$10)*$AG$10,2))) -> 85 | AH18: =IF($AG18="","",ROUND($AG18*$AH$10,2)) -> 17 | AI18: =IF(ISERROR(IF($AF18="","",ROUND(SUM($R18,$AE18,$AH18),2))),"",IF($AF18="","",ROUND(SUM($R18,$AE18,$AH18),2))) -> 87.25 | AJ18: =IF(ISERROR(IF($AF18="","",VLOOKUP(AI18,TRANSMUTATION_TABLE,4,TRUE))),"",IF($AF18="","",VLOOKUP(AI18,TRANSMUTATION_TABLE,4,TRUE))) -> 92 | AK18: 84 | AN18: 87 | AO18: 88
A19: 8 | B19: ='INPUT DATA'!B19 -> ORILLOS, Xian Gabriel B. | D19: 0 | F19: 13 | G19: 16 | H19: 13 | P19: =IF(COUNT($F19:$O19)=0,"",SUM($F19:$O19)) -> 42 | Q19: =IF(ISERROR(IF($P19="","",ROUND(($P19/$P$10)*$Q$10,2))),"",IF($P19="","",ROUND(($P19/$P$10)*$Q$10,2))) -> 76.36 | R19: =IF($Q19="","",ROUND($Q19*$R$10,2)) -> 22.91 | S19: 9 | T19: 4 | U19: 17 | V19: 4 | AC19: =IF(COUNT($S19:$AB19)=0,"",SUM($S19:$AB19)) -> 34 | AD19: =IF(ISERROR(IF($AC19="","",ROUND(($AC19/$AC$10)*$AD$10,2))),"",IF($AC19="","",ROUND(($AC19/$AC$10)*$AD$10,2))) -> 85 | AE19: =IF($AD19="","",ROUND($AD19*$AE$10,2)) -> 42.5 | AF19: 30 | AG19: =IF(ISERROR(IF($AF19="","",ROUND(($AF19/$AF$10)*$AG$10,2))),"",IF($AF19="","",ROUND(($AF19/$AF$10)*$AG$10,2))) -> 75 | AH19: =IF($AG19="","",ROUND($AG19*$AH$10,2)) -> 15 | AI19: =IF(ISERROR(IF($AF19="","",ROUND(SUM($R19,$AE19,$AH19),2))),"",IF($AF19="","",ROUND(SUM($R19,$AE19,$AH19),2))) -> 80.41 | AJ19: =IF(ISERROR(IF($AF19="","",VLOOKUP(AI19,TRANSMUTATION_TABLE,4,TRUE))),"",IF($AF19="","",VLOOKUP(AI19,TRANSMUTATION_TABLE,4,TRUE))) -> 87 | AK19: 82 | AN19: 83 | AO19: 84
A20: 9 | B20: ='INPUT DATA'!B20 -> OSOTEO, Clyne Jhay M. | F20: 16 | G20: 16 | H20: 13 | P20: =IF(COUNT($F20:$O20)=0,"",SUM($F20:$O20)) -> 45 | Q20: =IF(ISERROR(IF($P20="","",ROUND(($P20/$P$10)*$Q$10,2))),"",IF($P20="","",ROUND(($P20/$P$10)*$Q$10,2))) -> 81.82 | R20: =IF($Q20="","",ROUND($Q20*$R$10,2)) -> 24.55 | S20: 9 | T20: 4 | U20: 18 | V20: 5 | AC20: =IF(COUNT($S20:$AB20)=0,"",SUM($S20:$AB20)) -> 36 | AD20: =IF(ISERROR(IF($AC20="","",ROUND(($AC20/$AC$10)*$AD$10,2))),"",IF($AC20="","",ROUND(($AC20/$AC$10)*$AD$10,2))) -> 90 | AE20: =IF($AD20="","",ROUND($AD20*$AE$10,2)) -> 45 | AF20: 30 | AG20: =IF(ISERROR(IF($AF20="","",ROUND(($AF20/$AF$10)*$AG$10,2))),"",IF($AF20="","",ROUND(($AF20/$AF$10)*$AG$10,2))) -> 75 | AH20: =IF($AG20="","",ROUND($AG20*$AH$10,2)) -> 15 | AI20: =IF(ISERROR(IF($AF20="","",ROUND(SUM($R20,$AE20,$AH20),2))),"",IF($AF20="","",ROUND(SUM($R20,$AE20,$AH20),2))) -> 84.55 | AJ20: =IF(ISERROR(IF($AF20="","",VLOOKUP(AI20,TRANSMUTATION_TABLE,4,TRUE))),"",IF($AF20="","",VLOOKUP(AI20,TRANSMUTATION_TABLE,4,TRUE))) -> 90 | AK20: 85 | AN20: 88 | AO20: 89
A21: 10 | B21: ='INPUT DATA'!B21 -> OSOTEO, Jharie Liam A. | F21: 16 | G21: 13 | H21: 13 | P21: =IF(COUNT($F21:$O21)=0,"",SUM($F21:$O21)) -> 42 | Q21: =IF(ISERROR(IF($P21="","",ROUND(($P21/$P$10)*$Q$10,2))),"",IF($P21="","",ROUND(($P21/$P$10)*$Q$10,2))) -> 76.36 | R21: =IF($Q21="","",ROUND($Q21*$R$10,2)) -> 22.91 | S21: 9 | T21: 5 | U21: 18 | V21: 5 | AC21: =IF(COUNT($S21:$AB21)=0,"",SUM($S21:$AB21)) -> 37 | AD21: =IF(ISERROR(IF($AC21="","",ROUND(($AC21/$AC$10)*$AD$10,2))),"",IF($AC21="","",ROUND(($AC21/$AC$10)*$AD$10,2))) -> 92.5 | AE21: =IF($AD21="","",ROUND($AD21*$AE$10,2)) -> 46.25 | AF21: 32 | AG21: =IF(ISERROR(IF($AF21="","",ROUND(($AF21/$AF$10)*$AG$10,2))),"",IF($AF21="","",ROUND(($AF21/$AF$10)*$AG$10,2))) -> 80 | AH21: =IF($AG21="","",ROUND($AG21*$AH$10,2)) -> 16 | AI21: =IF(ISERROR(IF($AF21="","",ROUND(SUM($R21,$AE21,$AH21),2))),"",IF($AF21="","",ROUND(SUM($R21,$AE21,$AH21),2))) -> 85.16 | AJ21: =IF(ISERROR(IF($AF21="","",VLOOKUP(AI21,TRANSMUTATION_TABLE,4,TRUE))),"",IF($AF21="","",VLOOKUP(AI21,TRANSMUTATION_TABLE,4,TRUE))) -> 90 | AK21: 86 | AN21: 88 | AO21: 89
A22: 11 | B22: ='INPUT DATA'!B22 -> RONQUILLO, Benz Darylle H. | D22: 0 | F22: 18 | G22: 19 | H22: 13 | P22: =IF(COUNT($F22:$O22)=0,"",SUM($F22:$O22)) -> 50 | Q22: =IF(ISERROR(IF($P22="","",ROUND(($P22/$P$10)*$Q$10,2))),"",IF($P22="","",ROUND(($P22/$P$10)*$Q$10,2))) -> 90.91 | R22: =IF($Q22="","",ROUND($Q22*$R$10,2)) -> 27.27 | S22: 10 | T22: 5 | U22: 20 | V22: 5 | AC22: =IF(COUNT($S22:$AB22)=0,"",SUM($S22:$AB22)) -> 40 | AD22: =IF(ISERROR(IF($AC22="","",ROUND(($AC22/$AC$10)*$AD$10,2))),"",IF($AC22="","",ROUND(($AC22/$AC$10)*$AD$10,2))) -> 100 | AE22: =IF($AD22="","",ROUND($AD22*$AE$10,2)) -> 50 | AF22: 37 | AG22: =IF(ISERROR(IF($AF22="","",ROUND(($AF22/$AF$10)*$AG$10,2))),"",IF($AF22="","",ROUND(($AF22/$AF$10)*$AG$10,2))) -> 92.5 | AH22: =IF($AG22="","",ROUND($AG22*$AH$10,2)) -> 18.5 | AI22: =IF(ISERROR(IF($AF22="","",ROUND(SUM($R22,$AE22,$AH22),2))),"",IF($AF22="","",ROUND(SUM($R22,$AE22,$AH22),2))) -> 95.77 | AJ22: =IF(ISERROR(IF($AF22="","",VLOOKUP(AI22,TRANSMUTATION_TABLE,4,TRUE))),"",IF($AF22="","",VLOOKUP(AI22,TRANSMUTATION_TABLE,4,TRUE))) -> 97 | AK22: 91 | AN22: 93 | AO22: 96
A23: 12 | B23: ='INPUT DATA'!B23 -> SOMERA, Lucky Edward V. | C23: ='INPUT DATA'!C23 -> 0 | D23: ='INPUT DATA'!D23 -> 0 | E23: ='INPUT DATA'!E23 -> 0 | F23: 16 | G23: 18 | H23: 13 | P23: =IF(COUNT($F23:$O23)=0,"",SUM($F23:$O23)) -> 47 | Q23: =IF(ISERROR(IF($P23="","",ROUND(($P23/$P$10)*$Q$10,2))),"",IF($P23="","",ROUND(($P23/$P$10)*$Q$10,2))) -> 85.45 | R23: =IF($Q23="","",ROUND($Q23*$R$10,2)) -> 25.64 | S23: 9 | T23: 5 | U23: 19 | V23: 5 | AC23: =IF(COUNT($S23:$AB23)=0,"",SUM($S23:$AB23)) -> 38 | AD23: =IF(ISERROR(IF($AC23="","",ROUND(($AC23/$AC$10)*$AD$10,2))),"",IF($AC23="","",ROUND(($AC23/$AC$10)*$AD$10,2))) -> 95 | AE23: =IF($AD23="","",ROUND($AD23*$AE$10,2)) -> 47.5 | AF23: 34 | AG23: =IF(ISERROR(IF($AF23="","",ROUND(($AF23/$AF$10)*$AG$10,2))),"",IF($AF23="","",ROUND(($AF23/$AF$10)*$AG$10,2))) -> 85 | AH23: =IF($AG23="","",ROUND($AG23*$AH$10,2)) -> 17 | AI23: =IF(ISERROR(IF($AF23="","",ROUND(SUM($R23,$AE23,$AH23),2))),"",IF($AF23="","",ROUND(SUM($R23,$AE23,$AH23),2))) -> 90.14 | AJ23: =IF(ISERROR(IF($AF23="","",VLOOKUP(AI23,TRANSMUTATION_TABLE,4,TRUE))),"",IF($AF23="","",VLOOKUP(AI23,TRANSMUTATION_TABLE,4,TRUE))) -> 93 | AK23: 90 | AN23: 91 | AO23: 92
A24: 13 | B24: ='INPUT DATA'!B24 -> VILLAR, Jim Bruno A. | C24: ='INPUT DATA'!C24 -> 0 | D24: ='INPUT DATA'!D24 -> 0 | E24: ='INPUT DATA'!E24 -> 0 | F24: 17 | G24: 17 | H24: 14 | P24: =IF(COUNT($F24:$O24)=0,"",SUM($F24:$O24)) -> 48 | Q24: =IF(ISERROR(IF($P24="","",ROUND(($P24/$P$10)*$Q$10,2))),"",IF($P24="","",ROUND(($P24/$P$10)*$Q$10,2))) -> 87.27 | R24: =IF($Q24="","",ROUND($Q24*$R$10,2)) -> 26.18 | S24: 9 | T24: 5 | U24: 19 | V24: 5 | AC24: =IF(COUNT($S24:$AB24)=0,"",SUM($S24:$AB24)) -> 38 | AD24: =IF(ISERROR(IF($AC24="","",ROUND(($AC24/$AC$10)*$AD$10,2))),"",IF($AC24="","",ROUND(($AC24/$AC$10)*$AD$10,2))) -> 95 | AE24: =IF($AD24="","",ROUND($AD24*$AE$10,2)) -> 47.5 | AF24: 33 | AG24: =IF(ISERROR(IF($AF24="","",ROUND(($AF24/$AF$10)*$AG$10,2))),"",IF($AF24="","",ROUND(($AF24/$AF$10)*$AG$10,2))) -> 82.5 | AH24: =IF($AG24="","",ROUND($AG24*$AH$10,2)) -> 16.5 | AI24: =IF(ISERROR(IF($AF24="","",ROUND(SUM($R24,$AE24,$AH24),2))),"",IF($AF24="","",ROUND(SUM($R24,$AE24,$AH24),2))) -> 90.18 | AJ24: =IF(ISERROR(IF($AF24="","",VLOOKUP(AI24,TRANSMUTATION_TABLE,4,TRUE))),"",IF($AF24="","",VLOOKUP(AI24,TRANSMUTATION_TABLE,4,TRUE))) -> 93 | AK24: 87 | AN24: 89 | AO24: 90
P25: =IF(COUNT($F25:$O25)=0,"",SUM($F25:$O25)) | Q25: =IF(ISERROR(IF($P25="","",ROUND(($P25/$P$10)*$Q$10,2))),"",IF($P25="","",ROUND(($P25/$P$10)*$Q$10,2))) | R25: =IF($Q25="","",ROUND($Q25*$R$10,2)) | AC25: =IF(COUNT($S25:$AB25)=0,"",SUM($S25:$AB25)) | AD25: =IF(ISERROR(IF($AC25="","",ROUND(($AC25/$AC$10)*$AD$10,2))),"",IF($AC25="","",ROUND(($AC25/$AC$10)*$AD$10,2))) | AE25: =IF($AD25="","",ROUND($AD25*$AE$10,2)) | AG25: =IF(ISERROR(IF($AF25="","",ROUND(($AF25/$AF$10)*$AG$10,2))),"",IF($AF25="","",ROUND(($AF25/$AF$10)*$AG$10,2))) | AH25: =IF($AG25="","",ROUND($AG25*$AH$10,2)) | AI25: =IF(ISERROR(IF($AF25="","",ROUND(SUM($R25,$AE25,$AH25),2))),"",IF($AF25="","",ROUND(SUM($R25,$AE25,$AH25),2))) | AJ25: =IF(ISERROR(IF($AF25="","",VLOOKUP(AI25,TRANSMUTATION_TABLE,4,TRUE))),"",IF($AF25="","",VLOOKUP(AI25,TRANSMUTATION_TABLE,4,TRUE)))
B26: FEMALE | AG26: =IF(ISERROR(IF($AF26="","",ROUND(($AF26/$AF$10)*$AG$10,2))),"",IF($AF26="","",ROUND(($AF26/$AF$10)*$AG$10,2))) | AH26: =IF($AG26="","",ROUND($AG26*$AH$10,2))
A27: 1 | B27: ='INPUT DATA'!B30 -> CARDENAS, Zui Ai Gerryne A, | F27: 18 | G27: 17 | H27: 13 | P27: =IF(COUNT($F27:$O27)=0,"",SUM($F27:$O27)) -> 48 | Q27: =IF(ISERROR(IF($P27="","",ROUND(($P27/$P$10)*$Q$10,2))),"",IF($P27="","",ROUND(($P27/$P$10)*$Q$10,2))) -> 87.27 | R27: =IF($Q27="","",ROUND($Q27*$R$10,2)) -> 26.18 | S27: 10 | T27: 5 | U27: 19 | V27: 5 | AC27: =IF(COUNT($S27:$AB27)=0,"",SUM($S27:$AB27)) -> 39 | AD27: =IF(ISERROR(IF($AC27="","",ROUND(($AC27/$AC$10)*$AD$10,2))),"",IF($AC27="","",ROUND(($AC27/$AC$10)*$AD$10,2))) -> 97.5 | AE27: =IF($AD27="","",ROUND($AD27*$AE$10,2)) -> 48.75 | AF27: 31 | AG27: =IF(ISERROR(IF($AF27="","",ROUND(($AF27/$AF$10)*$AG$10,2))),"",IF($AF27="","",ROUND(($AF27/$AF$10)*$AG$10,2))) -> 77.5 | AH27: =IF($AG27="","",ROUND($AG27*$AH$10,2)) -> 15.5 | AI27: =IF(ISERROR(IF($AF27="","",ROUND(SUM($R27,$AE27,$AH27),2))),"",IF($AF27="","",ROUND(SUM($R27,$AE27,$AH27),2))) -> 90.43 | AJ27: =IF(ISERROR(IF($AF27="","",VLOOKUP(AI27,TRANSMUTATION_TABLE,4,TRUE))),"",IF($AF27="","",VLOOKUP(AI27,TRANSMUTATION_TABLE,4,TRUE))) -> 94 | AK27: 91 | AN27: 92 | AO27: 93
A28: 2 | B28: ='INPUT DATA'!B31 -> MAON, Kyle Rhean O. | F28: 16 | G28: 17 | H28: 13 | P28: =IF(COUNT($F28:$O28)=0,"",SUM($F28:$O28)) -> 46 | Q28: =IF(ISERROR(IF($P28="","",ROUND(($P28/$P$10)*$Q$10,2))),"",IF($P28="","",ROUND(($P28/$P$10)*$Q$10,2))) -> 83.64 | R28: =IF($Q28="","",ROUND($Q28*$R$10,2)) -> 25.09 | S28: 10 | T28: 5 | U28: 18 | V28: 5 | AC28: =IF(COUNT($S28:$AB28)=0,"",SUM($S28:$AB28)) -> 38 | AD28: =IF(ISERROR(IF($AC28="","",ROUND(($AC28/$AC$10)*$AD$10,2))),"",IF($AC28="","",ROUND(($AC28/$AC$10)*$AD$10,2))) -> 95 | AE28: =IF($AD28="","",ROUND($AD28*$AE$10,2)) -> 47.5 | AF28: 34 | AG28: =IF(ISERROR(IF($AF28="","",ROUND(($AF28/$AF$10)*$AG$10,2))),"",IF($AF28="","",ROUND(($AF28/$AF$10)*$AG$10,2))) -> 85 | AH28: =IF($AG28="","",ROUND($AG28*$AH$10,2)) -> 17 | AI28: =IF(ISERROR(IF($AF28="","",ROUND(SUM($R28,$AE28,$AH28),2))),"",IF($AF28="","",ROUND(SUM($R28,$AE28,$AH28),2))) -> 89.59 | AJ28: =IF(ISERROR(IF($AF28="","",VLOOKUP(AI28,TRANSMUTATION_TABLE,4,TRUE))),"",IF($AF28="","",VLOOKUP(AI28,TRANSMUTATION_TABLE,4,TRUE))) -> 93 | AK28: 86 | AN28: 90 | AO28: 92
A29: 3 | B29: ='INPUT DATA'!B32 -> MENDOZA, Ashley Keith O. | F29: 15 | G29: 16 | H29: 13 | P29: =IF(COUNT($F29:$O29)=0,"",SUM($F29:$O29)) -> 44 | Q29: =IF(ISERROR(IF($P29="","",ROUND(($P29/$P$10)*$Q$10,2))),"",IF($P29="","",ROUND(($P29/$P$10)*$Q$10,2))) -> 80 | R29: =IF($Q29="","",ROUND($Q29*$R$10,2)) -> 24 | S29: 8 | T29: 5 | U29: 17 | V29: 5 | AC29: =IF(COUNT($S29:$AB29)=0,"",SUM($S29:$AB29)) -> 35 | AD29: =IF(ISERROR(IF($AC29="","",ROUND(($AC29/$AC$10)*$AD$10,2))),"",IF($AC29="","",ROUND(($AC29/$AC$10)*$AD$10,2))) -> 87.5 | AE29: =IF($AD29="","",ROUND($AD29*$AE$10,2)) -> 43.75 | AF29: 30 | AG29: =IF(ISERROR(IF($AF29="","",ROUND(($AF29/$AF$10)*$AG$10,2))),"",IF($AF29="","",ROUND(($AF29/$AF$10)*$AG$10,2))) -> 75 | AH29: =IF($AG29="","",ROUND($AG29*$AH$10,2)) -> 15 | AI29: =IF(ISERROR(IF($AF29="","",ROUND(SUM($R29,$AE29,$AH29),2))),"",IF($AF29="","",ROUND(SUM($R29,$AE29,$AH29),2))) -> 82.75 | AJ29: =IF(ISERROR(IF($AF29="","",VLOOKUP(AI29,TRANSMUTATION_TABLE,4,TRUE))),"",IF($AF29="","",VLOOKUP(AI29,TRANSMUTATION_TABLE,4,TRUE))) -> 89 | AK29: 80 | AN29: 85 | AO29: 88
A30: 4 | B30: ='INPUT DATA'!B33 -> NERI, Arvienne P. | F30: 20 | G30: 20 | H30: 14 | P30: =IF(COUNT($F30:$O30)=0,"",SUM($F30:$O30)) -> 54 | Q30: =IF(ISERROR(IF($P30="","",ROUND(($P30/$P$10)*$Q$10,2))),"",IF($P30="","",ROUND(($P30/$P$10)*$Q$10,2))) -> 98.18 | R30: =IF($Q30="","",ROUND($Q30*$R$10,2)) -> 29.45 | S30: 10 | T30: 5 | U30: 20 | V30: 5 | AC30: =IF(COUNT($S30:$AB30)=0,"",SUM($S30:$AB30)) -> 40 | AD30: =IF(ISERROR(IF($AC30="","",ROUND(($AC30/$AC$10)*$AD$10,2))),"",IF($AC30="","",ROUND(($AC30/$AC$10)*$AD$10,2))) -> 100 | AE30: =IF($AD30="","",ROUND($AD30*$AE$10,2)) -> 50 | AF30: 35 | AG30: =IF(ISERROR(IF($AF30="","",ROUND(($AF30/$AF$10)*$AG$10,2))),"",IF($AF30="","",ROUND(($AF30/$AF$10)*$AG$10,2))) -> 87.5 | AH30: =IF($AG30="","",ROUND($AG30*$AH$10,2)) -> 17.5 | AI30: =IF(ISERROR(IF($AF30="","",ROUND(SUM($R30,$AE30,$AH30),2))),"",IF($AF30="","",ROUND(SUM($R30,$AE30,$AH30),2))) -> 96.95 | AJ30: =IF(ISERROR(IF($AF30="","",VLOOKUP(AI30,TRANSMUTATION_TABLE,4,TRUE))),"",IF($AF30="","",VLOOKUP(AI30,TRANSMUTATION_TABLE,4,TRUE))) -> 98 | AK30: 92 | AN30: 94 | AO30: 96
A31: 5 | B31: ='INPUT DATA'!B34 -> OPEÑA, Gracelyn May O. | F31: 17 | G31: 18 | H31: 14 | P31: =IF(COUNT($F31:$O31)=0,"",SUM($F31:$O31)) -> 49 | Q31: =IF(ISERROR(IF($P31="","",ROUND(($P31/$P$10)*$Q$10,2))),"",IF($P31="","",ROUND(($P31/$P$10)*$Q$10,2))) -> 89.09 | R31: =IF($Q31="","",ROUND($Q31*$R$10,2)) -> 26.73 | S31: 10 | T31: 5 | U31: 19 | V31: 5 | AC31: =IF(COUNT($S31:$AB31)=0,"",SUM($S31:$AB31)) -> 39 | AD31: =IF(ISERROR(IF($AC31="","",ROUND(($AC31/$AC$10)*$AD$10,2))),"",IF($AC31="","",ROUND(($AC31/$AC$10)*$AD$10,2))) -> 97.5 | AE31: =IF($AD31="","",ROUND($AD31*$AE$10,2)) -> 48.75 | AF31: 35 | AG31: =IF(ISERROR(IF($AF31="","",ROUND(($AF31/$AF$10)*$AG$10,2))),"",IF($AF31="","",ROUND(($AF31/$AF$10)*$AG$10,2))) -> 87.5 | AH31: =IF($AG31="","",ROUND($AG31*$AH$10,2)) -> 17.5 | AI31: =IF(ISERROR(IF($AF31="","",ROUND(SUM($R31,$AE31,$AH31),2))),"",IF($AF31="","",ROUND(SUM($R31,$AE31,$AH31),2))) -> 92.98 | AJ31: =IF(ISERROR(IF($AF31="","",VLOOKUP(AI31,TRANSMUTATION_TABLE,4,TRUE))),"",IF($AF31="","",VLOOKUP(AI31,TRANSMUTATION_TABLE,4,TRUE))) -> 95 | AK31: 91 | AN31: 93 | AO31: 94
A32: 6 | B32: ='INPUT DATA'!B35 -> PEÑAFIEL, Jandie V. | F32: 16 | G32: 17 | H32: 13 | P32: =IF(COUNT($F32:$O32)=0,"",SUM($F32:$O32)) -> 46 | Q32: =IF(ISERROR(IF($P32="","",ROUND(($P32/$P$10)*$Q$10,2))),"",IF($P32="","",ROUND(($P32/$P$10)*$Q$10,2))) -> 83.64 | R32: =IF($Q32="","",ROUND($Q32*$R$10,2)) -> 25.09 | S32: 10 | T32: 5 | U32: 19 | V32: 5 | AC32: =IF(COUNT($S32:$AB32)=0,"",SUM($S32:$AB32)) -> 39 | AD32: =IF(ISERROR(IF($AC32="","",ROUND(($AC32/$AC$10)*$AD$10,2))),"",IF($AC32="","",ROUND(($AC32/$AC$10)*$AD$10,2))) -> 97.5 | AE32: =IF($AD32="","",ROUND($AD32*$AE$10,2)) -> 48.75 | AF32: 30 | AG32: =IF(ISERROR(IF($AF32="","",ROUND(($AF32/$AF$10)*$AG$10,2))),"",IF($AF32="","",ROUND(($AF32/$AF$10)*$AG$10,2))) -> 75 | AH32: =IF($AG32="","",ROUND($AG32*$AH$10,2)) -> 15 | AI32: =IF(ISERROR(IF($AF32="","",ROUND(SUM($R32,$AE32,$AH32),2))),"",IF($AF32="","",ROUND(SUM($R32,$AE32,$AH32),2))) -> 88.84 | AJ32: =IF(ISERROR(IF($AF32="","",VLOOKUP(AI32,TRANSMUTATION_TABLE,4,TRUE))),"",IF($AF32="","",VLOOKUP(AI32,TRANSMUTATION_TABLE,4,TRUE))) -> 93 | AK32: 90 | AN32: 91 | AO32: 91
A33: 7 | B33: ='INPUT DATA'!B36 -> RIVERA, Eliska Catalina O. | F33: 20 | G33: 20 | H33: 13 | P33: =IF(COUNT($F33:$O33)=0,"",SUM($F33:$O33)) -> 53 | Q33: =IF(ISERROR(IF($P33="","",ROUND(($P33/$P$10)*$Q$10,2))),"",IF($P33="","",ROUND(($P33/$P$10)*$Q$10,2))) -> 96.36 | R33: =IF($Q33="","",ROUND($Q33*$R$10,2)) -> 28.91 | S33: 10 | T33: 5 | U33: 20 | V33: 5 | AC33: =IF(COUNT($S33:$AB33)=0,"",SUM($S33:$AB33)) -> 40 | AD33: =IF(ISERROR(IF($AC33="","",ROUND(($AC33/$AC$10)*$AD$10,2))),"",IF($AC33="","",ROUND(($AC33/$AC$10)*$AD$10,2))) -> 100 | AE33: =IF($AD33="","",ROUND($AD33*$AE$10,2)) -> 50 | AF33: 39 | AG33: =IF(ISERROR(IF($AF33="","",ROUND(($AF33/$AF$10)*$AG$10,2))),"",IF($AF33="","",ROUND(($AF33/$AF$10)*$AG$10,2))) -> 97.5 | AH33: =IF($AG33="","",ROUND($AG33*$AH$10,2)) -> 19.5 | AI33: =IF(ISERROR(IF($AF33="","",ROUND(SUM($R33,$AE33,$AH33),2))),"",IF($AF33="","",ROUND(SUM($R33,$AE33,$AH33),2))) -> 98.41 | AJ33: =IF(ISERROR(IF($AF33="","",VLOOKUP(AI33,TRANSMUTATION_TABLE,4,TRUE))),"",IF($AF33="","",VLOOKUP(AI33,TRANSMUTATION_TABLE,4,TRUE))) -> 99 | AK33: 97 | AN33: 98 | AO33: 99
A34: 8 | B34: ='INPUT DATA'!B37 -> VALDEZ, Angel Noreen R. | F34: 17 | G34: 16 | H34: 13 | P34: =IF(COUNT($F34:$O34)=0,"",SUM($F34:$O34)) -> 46 | Q34: =IF(ISERROR(IF($P34="","",ROUND(($P34/$P$10)*$Q$10,2))),"",IF($P34="","",ROUND(($P34/$P$10)*$Q$10,2))) -> 83.64 | R34: =IF($Q34="","",ROUND($Q34*$R$10,2)) -> 25.09 | S34: 10 | T34: 5 | U34: 19 | V34: 5 | AC34: =IF(COUNT($S34:$AB34)=0,"",SUM($S34:$AB34)) -> 39 | AD34: =IF(ISERROR(IF($AC34="","",ROUND(($AC34/$AC$10)*$AD$10,2))),"",IF($AC34="","",ROUND(($AC34/$AC$10)*$AD$10,2))) -> 97.5 | AE34: =IF($AD34="","",ROUND($AD34*$AE$10,2)) -> 48.75 | AF34: 34 | AG34: =IF(ISERROR(IF($AF34="","",ROUND(($AF34/$AF$10)*$AG$10,2))),"",IF($AF34="","",ROUND(($AF34/$AF$10)*$AG$10,2))) -> 85 | AH34: =IF($AG34="","",ROUND($AG34*$AH$10,2)) -> 17 | AI34: =IF(ISERROR(IF($AF34="","",ROUND(SUM($R34,$AE34,$AH34),2))),"",IF($AF34="","",ROUND(SUM($R34,$AE34,$AH34),2))) -> 90.84 | AJ34: =IF(ISERROR(IF($AF34="","",VLOOKUP(AI34,TRANSMUTATION_TABLE,4,TRUE))),"",IF($AF34="","",VLOOKUP(AI34,TRANSMUTATION_TABLE,4,TRUE))) -> 94 | AK34: 91 | AN34: 92 | AO34: 93
A35: 9 | B35: ='INPUT DATA'!B38 -> VILLAR, Veronica Mae F. | F35: 13 | G35: 19 | H35: 13 | P35: =IF(COUNT($F35:$O35)=0,"",SUM($F35:$O35)) -> 45 | Q35: =IF(ISERROR(IF($P35="","",ROUND(($P35/$P$10)*$Q$10,2))),"",IF($P35="","",ROUND(($P35/$P$10)*$Q$10,2))) -> 81.82 | R35: =IF($Q35="","",ROUND($Q35*$R$10,2)) -> 24.55 | S35: 9 | T35: 5 | U35: 18 | V35: 4 | AC35: =IF(COUNT($S35:$AB35)=0,"",SUM($S35:$AB35)) -> 36 | AD35: =IF(ISERROR(IF($AC35="","",ROUND(($AC35/$AC$10)*$AD$10,2))),"",IF($AC35="","",ROUND(($AC35/$AC$10)*$AD$10,2))) -> 90 | AE35: =IF($AD35="","",ROUND($AD35*$AE$10,2)) -> 45 | AF35: 30 | AG35: =IF(ISERROR(IF($AF35="","",ROUND(($AF35/$AF$10)*$AG$10,2))),"",IF($AF35="","",ROUND(($AF35/$AF$10)*$AG$10,2))) -> 75 | AH35: =IF($AG35="","",ROUND($AG35*$AH$10,2)) -> 15 | AI35: =IF(ISERROR(IF($AF35="","",ROUND(SUM($R35,$AE35,$AH35),2))),"",IF($AF35="","",ROUND(SUM($R35,$AE35,$AH35),2))) -> 84.55 | AJ35: =IF(ISERROR(IF($AF35="","",VLOOKUP(AI35,TRANSMUTATION_TABLE,4,TRUE))),"",IF($AF35="","",VLOOKUP(AI35,TRANSMUTATION_TABLE,4,TRUE))) -> 90 | AK35: 84 | AN35: 87 | AO35: 88
A36: 10 | B36: ='INPUT DATA'!B39 -> 0 | P36: =IF(COUNT($F36:$O36)=0,"",SUM($F36:$O36)) | Q36: =IF(ISERROR(IF($P36="","",ROUND(($P36/$P$10)*$Q$10,2))),"",IF($P36="","",ROUND(($P36/$P$10)*$Q$10,2))) | R36: =IF($Q36="","",ROUND($Q36*$R$10,2)) | AC36: =IF(COUNT($S36:$AB36)=0,"",SUM($S36:$AB36)) | AD36: =IF(ISERROR(IF($AC36="","",ROUND(($AC36/$AC$10)*$AD$10,2))),"",IF($AC36="","",ROUND(($AC36/$AC$10)*$AD$10,2))) | AE36: =IF($AD36="","",ROUND($AD36*$AE$10,2)) | AG36: =IF(ISERROR(IF($AF36="","",ROUND(($AF36/$AF$10)*$AG$10,2))),"",IF($AF36="","",ROUND(($AF36/$AF$10)*$AG$10,2))) | AH36: =IF($AG36="","",ROUND($AG36*$AH$10,2)) | AI36: =IF(ISERROR(IF($AF36="","",ROUND(SUM($R36,$AE36,$AH36),2))),"",IF($AF36="","",ROUND(SUM($R36,$AE36,$AH36),2))) | AJ36: =IF(ISERROR(IF($AF36="","",VLOOKUP(AI36,TRANSMUTATION_TABLE,4,TRUE))),"",IF($AF36="","",VLOOKUP(AI36,TRANSMUTATION_TABLE,4,TRUE)))
F37: =SUM(F12:F36) -> 360 | G37: =SUM(G12:G36) -> 376 | H37: =SUM(H12:H36) -> 291 | I37: =SUM(I12:I36) -> 0 | AF37: =SUM(AF12:AF36) -> 723
A38: MEAN | F38: =(SUM(F12:F36))/21 -> 17.142857 | G38: =(SUM(G12:G36))/21 -> 17.904762 | H38: =(SUM(H12:H36))/21 -> 13.857143 | I38: =(SUM(I12:I36))/21 -> 0 | AF38: =(SUM(AF12:AF36))/21 -> 34.428571
A39: % OF MASTERY | F39: =F38/F10*100 -> 85.714286 | G39: =G38/G10*100 -> 89.52381 | H39: =H38/H10*100 -> 92.380952 | I39: =I38/I10*100 -> #DIV/0! | AF39: =AF38/AF10*100 -> 86.071429
A41: Prepared by: | R41: Noted:
B42: ROSEL E. SANCHEZ | S42: ROMELYN O. OBALLES
B43: Master Teacher I | S43: Head Teacher III

Sheet MATH_Q4
A1: Class Record
A3: (Pursuant to Deped Order 8 series of 2015)
C4: REGION | G4: ='INPUT DATA'!G4 -> 1 | L4: DIVISION | O4: ='INPUT DATA'!O4 -> LA UNION | T4: DISTRICT | X4: ='INPUT DATA'!X4 -> BALAOAN
B5: SCHOOL NAME | G5: ='INPUT DATA'!G5 -> MASUPE ELEMENTARY SCHOOL | T5: SCHOOL ID | X5: ='INPUT DATA'!X5 -> 100882 | AD5: SCHOOL YEAR | AG5: ='INPUT DATA'!AG5 -> 2025 - 2026
